Workbook
Name 할인율: 입력!$C$2
Name 할인율퍼센트: 입력!$C$3
Name 연일수: 입력!$C$4
Name 총투자자산: 입력!$C$5
Name 유휴비율: 입력!$C$6
Name 투자실행액목표: 입력!$C$7
Name 순현금: 입력!$C$8
Name 가맹점평균: 입력!$C$9
Name 기준일: 입력!$C$10
Name 축시작: 입력!$C$11
Name 일별시작: 입력!$C$12
Name 일별종료: 입력!$C$13
Name 조회시작: 입력!$C$14
Name 조회종료: 입력!$C$15
Name 표본시작: 입력!$C$16
Name 표본종료: 입력!$C$17
Name 지시대상3: 입력!$C$18
Name 산식5: 입력!$C$19
Name SW_모집단: 입력!$B$22
Name SW_자릿수: 입력!$B$23
Name SW_가맹점수: 입력!$B$24
Name SW_방향: 입력!$B$25
Name 플랫폼코드범위: 입력!$A$28:$A$31
Name 플랫폼명범위: 입력!$B$28:$B$31
Name 구성비범위: 입력!$C$28:$C$31
Name 미지급률범위: 입력!$D$28:$D$31
Name 과지급률범위: 입력!$E$28:$E$31
Name 실측금액범위: 입력!$B$35:$B$38
Name 배달배분범위: 입력!$D$36:$D$38
Name 배달앱금액비중: 입력!$C$40
Name MAU배분범위: 입력!$C$43:$C$45
Name 배달앱비중: 입력!$B$47
Name 순번범위: 입력!$A$50:$A$57
Name 상호범위: 입력!$C$50:$C$57
Name flow범위: 입력!$G$50:$G$57
Name b범위: 입력!$H$50:$H$57
Name 하루입력범위: 입력!$I$50:$I$57
Name 계약상태범위: 입력!$J$50:$J$57
Name 평균금융일수범위: 플랫폼!$D$9:$D$12
Name Ed2범위: 플랫폼!$E$9:$E$12

Sheet 읽는 법
A1: # | B1: 화면 ↔ 엑셀 갈림 | C1: 까닭 | D1: 화면대조 행 | E1: 엑셀 값 | F1: 화면 표시값 | G1: 차이
A2: 1 | B2: 조회기간 ④(%) | C2: =화면대조!H170 | D2: 화면대조 170행 | E2: =화면대조!C170 | F2: =화면대조!E170 | G2: =화면대조!F170
A3: 2 | B3: 조회기간 ⑤(%) | C3: =화면대조!H171 | D3: 화면대조 171행 | E3: =화면대조!C171 | F3: =화면대조!E171 | G3: =화면대조!F171
A4: 3 | B4: 조회기간 PA | C4: =화면대조!H167 | D4: 화면대조 167행 | E4: =화면대조!C167 | F4: =화면대조!E167 | G4: =화면대조!F167
A5: 4 | B5: 조회기간 PwD | C5: =화면대조!H168 | D5: 화면대조 168행 | E5: =화면대조!C168 | F5: =화면대조!E168 | G5: =화면대조!F168
A6: 5 | B6: S입금부족율 raw(%) | C6: =화면대조!H175 | D6: 화면대조 175행 | E6: =화면대조!C175 | F6: =화면대조!E175 | G6: =화면대조!F175
A7: 6 | B7: 채권 건수 | C7: =화면대조!H176 | D7: 화면대조 176행 | E7: =화면대조!C176 | F7: =화면대조!E176 | G7: =화면대조!F176
A9: 순서 | B9: 시트 | C9: 무엇 | D9: 주요 칸
A10: 1 | B10: 읽는 법 | C10: 화면 ↔ 엑셀 갈림 6줄 · 시트 차례 · 화면 표시값 되짚는 경로 3줄 · 시뮬레이션 입력 칸 · 기호 규칙 · 대표 DM 2026-08-31 | D10: A1:G7 · 이 시트
A11: 2 | B11: 입력 | C11: 가정값 18칸 · 스위치 4칸 · 플랫폼 구성비 · 금액 실측 · 대표 엑셀 MAU 참고값 · 로스터 8곳 · 엑셀 프리셋 6종 | D11: C2:C17 · B22:B25 · C28:C31 · A50:K57
A12: 3 | B12: 플랫폼 | C12: 금융일수 도수분포(1~13일) · 평균 금융일수 · 구성비 가중 W금융일수 | D12: C2:O5 · D9:D12 · B17
A13: 4 | B13: 가맹점 | C13: 로스터 8곳의 플랫폼 배분 · 하루 선정산액 · 투자실행액 · W · S · Ty · 비중(최대잉여법) | D13: J2:M9 · O2:O9 · P2:P9 · AC2:AC9
A14: 5 | B14: 채권 | C14: (가맹점 x 플랫폼 x 선정산일 40일) 1,280건 원장 — 값 셀은 금융일수 Di 하나뿐 | D14: H열 Di · J열 Ai · Q열 미회수 · S열 Ai x Di
A15: 6 | B15: 일별 | C15: 정산예정일 27일치 집계 — 상환액 · 투자실행금 · 투자수익 · W · ty수익율 | D15: C2:E28 · H2:H28 · I2:I28
A16: 7 | B16: 기간집계 | C16: 조회기간 집계 2~29행 · 모집단별 W·Ty·S 32~60행 | D16: B5 · B13 · B17 · B41 · B42 · B51
A17: 8 | B17: 가중치 대조 | C17: 금액 실측 · 대표 엑셀 MAU · 로스터 금액가중 세 기준을 나란히 | D17: C17:E17 · C19:E19
A18: 9 | B18: 화면대조 | C18: 화면 표시값 원본 40행 · 불변식 · 화면 정합 162행 · 모델 잔차 28행 | D18: E열 화면 표시값 · G열 판정 · 166~193행 모델 잔차
A19: 10 | B19: 산식 | C19: 대표 정의서 45줄 ↔ 이 통합문서의 셀 | D19: C열
A21: # | B21: 화면 표시값 | C21: 값 | D21: 되짚는 경로
A22: 1 | B22: 투자실행액 | C22: =화면대조!E2 | D22: 입력 C7 → 가맹점 B14 → 가맹점 P2:P9 → 채권 J2:J1281 (Q열=1) → 기간집계 B38 → B44
A23: 2 | B23: W금융일수 표기 | C23: =화면대조!E8 | D23: 플랫폼 C2:O5 → 플랫폼 D9:D12 → 가맹점 O2:O9 → 채권 S2:S1281 → 기간집계 B41 → B42
A24: 3 | B24: Ty수익율(%) | C24: =화면대조!E9 | D24: 입력 C3 · 입력 C4 · 기간집계 B42 → 기간집계 B43
A26: # | B26: 바꾸는 칸 | C26: 항목 | D26: 지금 값 | E26: 움직이는 값
A27: 1 | B27: 입력 C5 | C27: 총 투자자산 | D27: =총투자자산 | E27: 입력 C7 · C8 → 채권 I·J열 → 기간집계 B44 · B45 · B46
A28: 2 | B28: 입력 C6 | C28: 유휴 비율 | D28: =유휴비율 | E28: 입력 C7 · C8 → 기간집계 B47 · B48 · B17(⑤)
A29: 3 | B29: 입력 B22 | C29: 스위치 ① W금융일수 모집단 | D29: =SW_모집단 | E29: 기간집계 B41 · B42 · B43
A30: 4 | B30: 입력 B23 | C30: 스위치 ② W 표기 자릿수 | D30: =SW_자릿수 | E30: 기간집계 B42 · B43
A31: 5 | B31: 입력 B24 | C31: 스위치 ③ 가맹점 수 | D31: =SW_가맹점수 | E31: 가맹점 G열 → 가맹점 B19 · B16
A32: 6 | B32: 입력 B25 | C32: 스위치 ④ 산출 방향 | D32: =SW_방향 | E32: 가맹점 P열 → 가맹점 B16
A33: 7 | B33: 입력 C28:C31 | C33: 플랫폼 구성비 | D33: =SUM(구성비범위) | E33: 플랫폼 B17 · 가맹점 O열 · '가중치 대조' C17
A34: 8 | B34: 입력 C14:C15 | C34: 조회기간 | D34: =조회종료-조회시작+1 | E34: 기간집계 2~29행
A35: 9 | B35: 입력 C10 | C35: 기준일 d | D35: =기준일 | E35: 채권 F·G열 · 일별 A열 · 채권 Q·R·T·U열
A36: 10 | B36: 입력 C18 | C36: ③ 지시 대상 (미확정) | D36: =지시대상3 | E36: 기간집계 B18(⑥) — 비어 있는 동안 ⑥ 은 「미확정」
A37: 11 | B37: 입력 C19 | C37: ⑤ 산식 (미확정 · 대표 재작성 대기) | D37: =산식5 | E37: 기간집계 B17(⑤) → 기간집계 B18(⑥) → 화면대조 모델 잔차 「조회기간 ⑤(%)」
A38: 12 | B38: 입력 B47 | C38: 배달앱/전체 (대표 엑셀 MAU 쪽 계산) | D38: =배달앱비중 | E38: '가중치 대조' D17 · D19 — 참고값 계열
A40: # | B40: 기호 | C40: 갈래 | D40: 뜻 | E40: 이 통합문서의 자리 | F40: 출처
A41: 1 | B41: d | D41: 현재일자 | E41: 입력 C10 기준일 d | F41: dm_0901/symbol_rule_0901.md
A42: 2 | B42: r | D42: 유동화투자자의 할인율 | E42: 입력 C2 · C3 | F42: dm_0901/symbol_rule_0901.md
A43: 3 | B43: D | C43: 개념 | D43: 금융일수 | E43: 채권 H열 | F43: dm_0901/symbol_rule_0901.md
A44: 4 | B44: Y | C44: 개념 | D44: 연환산수익률. Yr · YMR(d-1) · PYMR · wPYMR 로 갈린다 | E44: 기간집계 B43 · 일별 I열 · 기간집계 B13 · B17 | F44: dm_0901/symbol_rule_0901.md
...

Sheet 입력
A1: 구분 | B1: 항목 | C1: 값 | D1: 단위 | E1: 출처
A2: 요율 | B2: 유동화투자자의 할인율 | C2: 0.0011 | D2: 비율 | E2: ceo_definitions.md [1번 이미지]
A3: 요율 | B3: 할인율(%) | C3: =C2*100 | D3: % | E3: C2 x 100
A4: 요율 | B4: 연일수 | C4: 365 | D4: 일 | E4: ceo_definitions.md ty수익율
A5: 규모 | B5: 총 투자자산 | C5: 100000000 | D5: 원 | E5: ledger_facts.json total
A6: 규모 | B6: 유휴 비율 | C6: 0.3 | D6: 비율 | E6: 순현금 / 투자자산 (cash / total)
A7: 규모 | B7: 투자실행액 목표 | C7: =C5-C8 | D7: 원 | E7: C5 - C8 = 총 투자자산 x (1 - 유휴 비율)
A8: 규모 | B8: 순현금 | C8: =ROUND(C5*C6,0) | D8: 원 | E8: C5 x C6 = 총 투자자산 x 유휴 비율
A9: 규모 | B9: 가맹점 평균 하루 선정산액 | C9: 3287500 | D9: 원 | E9: daily_ledger.py BOOKROWS — Σ flow / 곳수
A10: 기간 | B10: 기준일 d | C10: 46261 | D10: 날짜 | E10: daily_ledger.py ASOF
A11: 기간 | B11: 선정산일 축 시작 | C11: =C10-39 | D11: 날짜 | E11: 축 40일
A12: 기간 | B12: 일별 표 시작 | C12: =C10-26 | D12: 날짜 | E12: 전량 커버 구간 시작
A13: 기간 | B13: 일별 표 종료 | C13: =C10 | D13: 날짜 | E13: 기준일
A14: 기간 | B14: 조회기간 시작 | C14: =C10-6 | D14: 날짜 | E14: ceo_definitions.md default 일주일
A15: 기간 | B15: 조회기간 종료 | C15: =C10 | D15: 날짜 | E15: 기준일
A16: 기간 | B16: S표본 시작 | C16: =C10-20 | D16: 날짜 | E16: ceo_definitions.md 표본집합 d-20
A17: 기간 | B17: S표본 종료 | C17: =C10-11 | D17: 날짜 | E17: ceo_definitions.md 표본집합 d-11
A18: 산식 | B18: ③ 지시 대상 (미확정) | D18: 원 | E18: ceo_definitions.md [2번] 이미지의 ③ — 「상단 현황의 기간 전체 숫자」까지만 좁혀짐. 칸 미확정 (U-03 · F-23)
A19: 산식 | B19: ⑤ 산식 (미확정 · 대표 재작성 대기) | C19: =IF(기간집계!B5+기간집계!B15=0,0,ROUND(기간집계!B13*기간집계!B5/(기간집계!B5+기간집계!B15),6)) | D19: % | E19: ceo_definitions.md [2번] 이미지의 ⑤ — 이 칸 하나만 갈아 끼우면 기간집계 ⑤ 와 ⑥ 이 따라온다. 대표 재작성 대기 (A-01)
A21: 스위치 | B21: 선택 | C21: 선택지 | D21: 산출 위치
A22: ① W금융일수 모집단 | B22: 대상정산금채권 전체 | C22: 대상정산금채권 전체 / 만기 도래분만 / 미회수 잔량만 | D22: 기간집계 B41
A23: ② W 표기 자릿수 | B23: 2 | C23: 1 / 2 | D23: 기간집계 B42
A24: ③ 가맹점 수 | B24: 8 | C24: 1 ~ 8 | D24: 가맹점 G열
A25: ④ 산출 방향 | B25: A | C25: A 자산에서 출발 / B 가맹점에서 출발 | D25: 가맹점 P열
A27: 코드 | B27: 플랫폼 | C27: 구성비 (입력) | D27: 미지급률 | E27: 과지급률 | F27: 출처
A28: card | B28: 카드사 | C28: 0.42834443 | D28: 0.00025 | E28: 0.0001 | F28: platform_duration.py BOOK_MIX · UNPAID · OVERPAID
A29: bm | B29: 배달의민족 | C29: 0.43100793 | D29: 0.0014 | E29: 0.00045 | F29: platform_duration.py BOOK_MIX · UNPAID · OVERPAID
A30: cpe | B30: 쿠팡이츠 | C30: 0.095521643 | D30: 0.0021 | E30: 0.00055 | F30: platform_duration.py BOOK_MIX · UNPAID · OVERPAID
A31: yo | B31: 요기요 | C31: 0.045125998 | D31: 0.003 | E31: 0.00075 | F31: platform_duration.py BOOK_MIX · UNPAID · OVERPAID
B32: 합계 | C32: =SUM(C28:C31)
A34: 플랫폼 | B34: 하루 순지급액(원) | C34: 구성비 | D34: 배달 3사 내부 배분 | E34: 출처
A35: 카드사 | B35: 253935 | C35: =B35/$B$39 | E35: Figma 2782:5879 · 미리 받는 돈 상세 (analysis/figma_02_가맹점화면.md §3-2)
A36: 배달의민족 | B36: 255514 | C36: =B36/$B$39 | D36: =B36/$B$40
A37: 쿠팡이츠 | B37: 56628 | C37: =B37/$B$39 | D37: =B37/$B$40
A38: 요기요 | B38: 26752 | C38: =B38/$B$39 | D38: =B38/$B$40
A39: 합계 | B39: =SUM(B35:B38) | C39: =SUM(C35:C38)
A40: 배달 3사 합 | B40: =SUM(B36:B38) | C40: =B40/B39 | D40: =SUM(D36:D38) | E40: 배달앱/전체 (금액 실측)
A42: 배달앱 | B42: MAU | C42: 배달 3사 내부 배분 | D42: 출처
A43: 배민 | B43: 2175 | C43: =B43/$B$46 | D43: 정산주기.xlsx 비중 D4:F4
A44: 쿠팡이츠 | B44: 1044 | C44: =B44/$B$46 | D44: 정산주기.xlsx 비중 D4:F4
...

Sheet 플랫폼
A1: 코드 | B1: 플랫폼 | C1: 1 | D1: 2 | E1: 3 | F1: 4 | G1: 5 | H1: 6 | I1: 7 | J1: 8 | K1: 9 | L1: 10 | M1: 11 | N1: 12 | O1: 13 | P1: 도수 합 | Q1: Σ(d x 도수) | R1: Σ(d² x 도수)
A2: card | B2: 카드사 | C2: 189 | D2: 53 | E2: 96 | F2: 12 | G2: 4 | H2: 2 | I2: 3 | J2: 3 | K2: 2 | L2: 1 | M2: 0 | N2: 0 | O2: 0 | P2: =SUM(C2:O2) | Q2: =SUMPRODUCT($C$1:$O$1,C2:O2) | R2: =SUMPRODUCT($C$1:$O$1,$C$1:$O$1,C2:O2)
A3: bm | B3: 배달의민족 | C3: 0 | D3: 138 | E3: 52 | F3: 139 | G3: 18 | H3: 6 | I3: 2 | J3: 2 | K3: 3 | L3: 3 | M3: 2 | N3: 0 | O3: 0 | P3: =SUM(C3:O3) | Q3: =SUMPRODUCT($C$1:$O$1,C3:O3) | R3: =SUMPRODUCT($C$1:$O$1,$C$1:$O$1,C3:O3)
A4: cpe | B4: 쿠팡이츠 | C4: 0 | D4: 0 | E4: 89 | F4: 48 | G4: 177 | H4: 24 | I4: 8 | J4: 4 | K4: 4 | L4: 4 | M4: 3 | N4: 4 | O4: 0 | P4: =SUM(C4:O4) | Q4: =SUMPRODUCT($C$1:$O$1,C4:O4) | R4: =SUMPRODUCT($C$1:$O$1,$C$1:$O$1,C4:O4)
A5: yo | B5: 요기요 | C5: 0 | D5: 0 | E5: 0 | F5: 43 | G5: 43 | H5: 211 | I5: 27 | J5: 13 | K5: 7 | L5: 7 | M5: 3 | N5: 5 | O5: 6 | P5: =SUM(C5:O5) | Q5: =SUMPRODUCT($C$1:$O$1,C5:O5) | R5: =SUMPRODUCT($C$1:$O$1,$C$1:$O$1,C5:O5)
B6: 합계 | P6: =SUM(P2:P5)
A8: 코드 | B8: 플랫폼 | C8: 구성비 | D8: 평균 금융일수 E[d] | E8: E[d²] | F8: E[d²]/E[d] | G8: 미지급률 | H8: 과지급률 | I8: 미지급-과지급 | J8: 대표 엑셀 평균 | K8: 차
A9: card | B9: 카드사 | C9: =INDEX(구성비범위,1) | D9: =Q2/P2 | E9: =R2/P2 | F9: =E9/D9 | G9: =INDEX(미지급률범위,1) | H9: =INDEX(과지급률범위,1) | I9: =G9-H9 | J9: 2.0164384 | K9: =D9-J9
A10: bm | B10: 배달의민족 | C10: =INDEX(구성비범위,2) | D10: =Q3/P3 | E10: =R3/P3 | F10: =E10/D10 | G10: =INDEX(미지급률범위,2) | H10: =INDEX(과지급률범위,2) | I10: =G10-H10 | J10: 3.3506849 | K10: =D10-J10
A11: cpe | B11: 쿠팡이츠 | C11: =INDEX(구성비범위,3) | D11: =Q4/P4 | E11: =R4/P4 | F11: =E11/D11 | G11: =INDEX(미지급률범위,3) | H11: =INDEX(과지급률범위,3) | I11: =G11-H11 | J11: 4.7479452 | K11: =D11-J11
A12: yo | B12: 요기요 | C12: =INDEX(구성비범위,4) | D12: =Q5/P5 | E12: =R5/P5 | F12: =E12/D12 | G12: =INDEX(미지급률범위,4) | H12: =INDEX(과지급률범위,4) | I12: =G12-H12 | J12: 6.1643836 | K12: =D12-J12
B13: 가중 | C13: =SUM(C9:C12) | D13: =SUMPRODUCT(C9:C12,D9:D12) | E13: =SUMPRODUCT(C9:C12,E9:E12) | F13: =E13/D13
A15: 항목 | B15: 값 | C15: 산식
A16: 구성비 합 | B16: =SUM(구성비범위) | C16: SUM(구성비)
A17: W금융일수 (구성비 x 평균 금융일수) | B17: =ROUND(SUMPRODUCT(구성비범위,평균금융일수범위),6) | C17: ROUND(Σ 구성비 x 평균 금융일수, 6)
A18: 대표 엑셀 MAU 시장 평균 참고값 H41 | B18: 2.7504069 | C18: 정산주기.xlsx 정산주기 H41
A19: 차 | B19: =B17-B18 | C19: B17 - B18
A20: 가중 E[d²] | B20: =SUMPRODUCT(구성비범위,Ed2범위) | C20: Σ 구성비 x E[d²]
A21: 미회수 이론 W | B21: =ROUND(B20/B17,6) | C21: ROUND(가중 E[d²] / W, 6)
A22: Ty수익율(%) — 구성비 W 기준 | B22: =ROUND(할인율퍼센트*연일수/ROUND(B17,SW_자릿수),6) | C22: 할인율 x 365 / 표기 W

Sheet 가맹점
A1: 순번 | B1: 사업자ID | C1: 상호 | D1: 업종 | E1: 품목 | F1: 계약일 | G1: 사용 | H1: flow 하루 선정산액 | I1: 배달 의존도 b | J1: 카드 | K1: 배민 | L1: 쿠팡이츠 | M1: 요기요 | N1: 구성비 합 | O1: 가맹점 w금융일수 | P1: 하루 선정산액 | Q1: 하루 Ai | R1: 투자실행액 | S1: 비중 raw | T1: 표기 W | U1: 가중 미지급률 | V1: 가중 과지급률 | W1: S입금부족율(%) | X1: Ty수익율(%) | Y1: 구간 | Z1: 비중 내림(pp) | AA1: 잔차(pp) | AB1: 잔차 순위 | AC1: 비중 표기(%) | AD1: 계약 상태
A2: =입력!A50 | B2: =입력!B50 | C2: =입력!C50 | D2: =입력!D50 | E2: =입력!E50 | F2: =입력!F50 | G2: =IF(A2<=SW_가맹점수,1,0) | H2: =입력!G50 | I2: =입력!H50 | J2: =G2*(1-I2) | K2: =G2*I2*INDEX(배달배분범위,1) | L2: =G2*I2*INDEX(배달배분범위,2) | M2: =G2*I2*INDEX(배달배분범위,3) | N2: =SUM(J2:M2) | O2: =J2*INDEX(평균금융일수범위,1)+K2*INDEX(평균금융일수범위,2)+L2*INDEX(평균금융일수범위,3)+M2*INDEX(평균금융일수범위,4) | P2: =IF(SW_방향="A",G2*H2*$B$15,G2*입력!I50) | Q2: =P2*(1-할인율) | R2: =P2*(1-할인율)*O2 | S2: =IF($R$10=0,0,R2/$R$10) | T2: =IF(G2=0,"",ROUND(ROUND(O2,6),SW_자릿수)) | U2: =J2*INDEX(미지급률범위,1)+K2*INDEX(미지급률범위,2)+L2*INDEX(미지급률범위,3)+M2*INDEX(미지급률범위,4) | V2: =J2*INDEX(과지급률범위,1)+K2*INDEX(과지급률범위,2)+L2*INDEX(과지급률범위,3)+M2*INDEX(과지급률범위,4) | W2: =IF(G2=0,"",ROUND((U2-V2)/(1-할인율)*100,6)) | X2: =IF(G2=0,"",ROUND(할인율퍼센트*연일수/ROUND(O2,6),6)) | Y2: =IF(G2=0,"",IF(P2>=5000000,"고액",IF(P2>=2000000,"평범","소액"))) | Z2: =IF(G2=0,"",ROUNDDOWN(S2*1000,0)/10) | AA2: =IF(G2=0,"",S2*100-Z2) | AB2: =IF(G2=0,"",RANK(AA2,$AA$2:$AA$9,0)+COUNTIF($AA$2:AA2,AA2)-1) | AC2: =IF(G2=0,"",Z2+IF(AB2<=$B$11,0.1,0)) | AD2: =입력!J50
A3: =입력!A51 | B3: =입력!B51 | C3: =입력!C51 | D3: =입력!D51 | E3: =입력!E51 | F3: =입력!F51 | G3: =IF(A3<=SW_가맹점수,1,0) | H3: =입력!G51 | I3: =입력!H51 | J3: =G3*(1-I3) | K3: =G3*I3*INDEX(배달배분범위,1) | L3: =G3*I3*INDEX(배달배분범위,2) | M3: =G3*I3*INDEX(배달배분범위,3) | N3: =SUM(J3:M3) | O3: =J3*INDEX(평균금융일수범위,1)+K3*INDEX(평균금융일수범위,2)+L3*INDEX(평균금융일수범위,3)+M3*INDEX(평균금융일수범위,4) | P3: =IF(SW_방향="A",G3*H3*$B$15,G3*입력!I51) | Q3: =P3*(1-할인율) | R3: =P3*(1-할인율)*O3 | S3: =IF($R$10=0,0,R3/$R$10) | T3: =IF(G3=0,"",ROUND(ROUND(O3,6),SW_자릿수)) | U3: =J3*INDEX(미지급률범위,1)+K3*INDEX(미지급률범위,2)+L3*INDEX(미지급률범위,3)+M3*INDEX(미지급률범위,4) | V3: =J3*INDEX(과지급률범위,1)+K3*INDEX(과지급률범위,2)+L3*INDEX(과지급률범위,3)+M3*INDEX(과지급률범위,4) | W3: =IF(G3=0,"",ROUND((U3-V3)/(1-할인율)*100,6)) | X3: =IF(G3=0,"",ROUND(할인율퍼센트*연일수/ROUND(O3,6),6)) | Y3: =IF(G3=0,"",IF(P3>=5000000,"고액",IF(P3>=2000000,"평범","소액"))) | Z3: =IF(G3=0,"",ROUNDDOWN(S3*1000,0)/10) | AA3: =IF(G3=0,"",S3*100-Z3) | AB3: =IF(G3=0,"",RANK(AA3,$AA$2:$AA$9,0)+COUNTIF($AA$2:AA3,AA3)-1) | AC3: =IF(G3=0,"",Z3+IF(AB3<=$B$11,0.1,0)) | AD3: =입력!J51
A4: =입력!A52 | B4: =입력!B52 | C4: =입력!C52 | D4: =입력!D52 | E4: =입력!E52 | F4: =입력!F52 | G4: =IF(A4<=SW_가맹점수,1,0) | H4: =입력!G52 | I4: =입력!H52 | J4: =G4*(1-I4) | K4: =G4*I4*INDEX(배달배분범위,1) | L4: =G4*I4*INDEX(배달배분범위,2) | M4: =G4*I4*INDEX(배달배분범위,3) | N4: =SUM(J4:M4) | O4: =J4*INDEX(평균금융일수범위,1)+K4*INDEX(평균금융일수범위,2)+L4*INDEX(평균금융일수범위,3)+M4*INDEX(평균금융일수범위,4) | P4: =IF(SW_방향="A",G4*H4*$B$15,G4*입력!I52) | Q4: =P4*(1-할인율) | R4: =P4*(1-할인율)*O4 | S4: =IF($R$10=0,0,R4/$R$10) | T4: =IF(G4=0,"",ROUND(ROUND(O4,6),SW_자릿수)) | U4: =J4*INDEX(미지급률범위,1)+K4*INDEX(미지급률범위,2)+L4*INDEX(미지급률범위,3)+M4*INDEX(미지급률범위,4) | V4: =J4*INDEX(과지급률범위,1)+K4*INDEX(과지급률범위,2)+L4*INDEX(과지급률범위,3)+M4*INDEX(과지급률범위,4) | W4: =IF(G4=0,"",ROUND((U4-V4)/(1-할인율)*100,6)) | X4: =IF(G4=0,"",ROUND(할인율퍼센트*연일수/ROUND(O4,6),6)) | Y4: =IF(G4=0,"",IF(P4>=5000000,"고액",IF(P4>=2000000,"평범","소액"))) | Z4: =IF(G4=0,"",ROUNDDOWN(S4*1000,0)/10) | AA4: =IF(G4=0,"",S4*100-Z4) | AB4: =IF(G4=0,"",RANK(AA4,$AA$2:$AA$9,0)+COUNTIF($AA$2:AA4,AA4)-1) | AC4: =IF(G4=0,"",Z4+IF(AB4<=$B$11,0.1,0)) | AD4: =입력!J52
A5: =입력!A53 | B5: =입력!B53 | C5: =입력!C53 | D5: =입력!D53 | E5: =입력!E53 | F5: =입력!F53 | G5: =IF(A5<=SW_가맹점수,1,0) | H5: =입력!G53 | I5: =입력!H53 | J5: =G5*(1-I5) | K5: =G5*I5*INDEX(배달배분범위,1) | L5: =G5*I5*INDEX(배달배분범위,2) | M5: =G5*I5*INDEX(배달배분범위,3) | N5: =SUM(J5:M5) | O5: =J5*INDEX(평균금융일수범위,1)+K5*INDEX(평균금융일수범위,2)+L5*INDEX(평균금융일수범위,3)+M5*INDEX(평균금융일수범위,4) | P5: =IF(SW_방향="A",G5*H5*$B$15,G5*입력!I53) | Q5: =P5*(1-할인율) | R5: =P5*(1-할인율)*O5 | S5: =IF($R$10=0,0,R5/$R$10) | T5: =IF(G5=0,"",ROUND(ROUND(O5,6),SW_자릿수)) | U5: =J5*INDEX(미지급률범위,1)+K5*INDEX(미지급률범위,2)+L5*INDEX(미지급률범위,3)+M5*INDEX(미지급률범위,4) | V5: =J5*INDEX(과지급률범위,1)+K5*INDEX(과지급률범위,2)+L5*INDEX(과지급률범위,3)+M5*INDEX(과지급률범위,4) | W5: =IF(G5=0,"",ROUND((U5-V5)/(1-할인율)*100,6)) | X5: =IF(G5=0,"",ROUND(할인율퍼센트*연일수/ROUND(O5,6),6)) | Y5: =IF(G5=0,"",IF(P5>=5000000,"고액",IF(P5>=2000000,"평범","소액"))) | Z5: =IF(G5=0,"",ROUNDDOWN(S5*1000,0)/10) | AA5: =IF(G5=0,"",S5*100-Z5) | AB5: =IF(G5=0,"",RANK(AA5,$AA$2:$AA$9,0)+COUNTIF($AA$2:AA5,AA5)-1) | AC5: =IF(G5=0,"",Z5+IF(AB5<=$B$11,0.1,0)) | AD5: =입력!J53
A6: =입력!A54 | B6: =입력!B54 | C6: =입력!C54 | D6: =입력!D54 | E6: =입력!E54 | F6: =입력!F54 | G6: =IF(A6<=SW_가맹점수,1,0) | H6: =입력!G54 | I6: =입력!H54 | J6: =G6*(1-I6) | K6: =G6*I6*INDEX(배달배분범위,1) | L6: =G6*I6*INDEX(배달배분범위,2) | M6: =G6*I6*INDEX(배달배분범위,3) | N6: =SUM(J6:M6) | O6: =J6*INDEX(평균금융일수범위,1)+K6*INDEX(평균금융일수범위,2)+L6*INDEX(평균금융일수범위,3)+M6*INDEX(평균금융일수범위,4) | P6: =IF(SW_방향="A",G6*H6*$B$15,G6*입력!I54) | Q6: =P6*(1-할인율) | R6: =P6*(1-할인율)*O6 | S6: =IF($R$10=0,0,R6/$R$10) | T6: =IF(G6=0,"",ROUND(ROUND(O6,6),SW_자릿수)) | U6: =J6*INDEX(미지급률범위,1)+K6*INDEX(미지급률범위,2)+L6*INDEX(미지급률범위,3)+M6*INDEX(미지급률범위,4) | V6: =J6*INDEX(과지급률범위,1)+K6*INDEX(과지급률범위,2)+L6*INDEX(과지급률범위,3)+M6*INDEX(과지급률범위,4) | W6: =IF(G6=0,"",ROUND((U6-V6)/(1-할인율)*100,6)) | X6: =IF(G6=0,"",ROUND(할인율퍼센트*연일수/ROUND(O6,6),6)) | Y6: =IF(G6=0,"",IF(P6>=5000000,"고액",IF(P6>=2000000,"평범","소액"))) | Z6: =IF(G6=0,"",ROUNDDOWN(S6*1000,0)/10) | AA6: =IF(G6=0,"",S6*100-Z6) | AB6: =IF(G6=0,"",RANK(AA6,$AA$2:$AA$9,0)+COUNTIF($AA$2:AA6,AA6)-1) | AC6: =IF(G6=0,"",Z6+IF(AB6<=$B$11,0.1,0)) | AD6: =입력!J54
A7: =입력!A55 | B7: =입력!B55 | C7: =입력!C55 | D7: =입력!D55 | E7: =입력!E55 | F7: =입력!F55 | G7: =IF(A7<=SW_가맹점수,1,0) | H7: =입력!G55 | I7: =입력!H55 | J7: =G7*(1-I7) | K7: =G7*I7*INDEX(배달배분범위,1) | L7: =G7*I7*INDEX(배달배분범위,2) | M7: =G7*I7*INDEX(배달배분범위,3) | N7: =SUM(J7:M7) | O7: =J7*INDEX(평균금융일수범위,1)+K7*INDEX(평균금융일수범위,2)+L7*INDEX(평균금융일수범위,3)+M7*INDEX(평균금융일수범위,4) | P7: =IF(SW_방향="A",G7*H7*$B$15,G7*입력!I55) | Q7: =P7*(1-할인율) | R7: =P7*(1-할인율)*O7 | S7: =IF($R$10=0,0,R7/$R$10) | T7: =IF(G7=0,"",ROUND(ROUND(O7,6),SW_자릿수)) | U7: =J7*INDEX(미지급률범위,1)+K7*INDEX(미지급률범위,2)+L7*INDEX(미지급률범위,3)+M7*INDEX(미지급률범위,4) | V7: =J7*INDEX(과지급률범위,1)+K7*INDEX(과지급률범위,2)+L7*INDEX(과지급률범위,3)+M7*INDEX(과지급률범위,4) | W7: =IF(G7=0,"",ROUND((U7-V7)/(1-할인율)*100,6)) | X7: =IF(G7=0,"",ROUND(할인율퍼센트*연일수/ROUND(O7,6),6)) | Y7: =IF(G7=0,"",IF(P7>=5000000,"고액",IF(P7>=2000000,"평범","소액"))) | Z7: =IF(G7=0,"",ROUNDDOWN(S7*1000,0)/10) | AA7: =IF(G7=0,"",S7*100-Z7) | AB7: =IF(G7=0,"",RANK(AA7,$AA$2:$AA$9,0)+COUNTIF($AA$2:AA7,AA7)-1) | AC7: =IF(G7=0,"",Z7+IF(AB7<=$B$11,0.1,0)) | AD7: =입력!J55
A8: =입력!A56 | B8: =입력!B56 | C8: =입력!C56 | D8: =입력!D56 | E8: =입력!E56 | F8: =입력!F56 | G8: =IF(A8<=SW_가맹점수,1,0) | H8: =입력!G56 | I8: =입력!H56 | J8: =G8*(1-I8) | K8: =G8*I8*INDEX(배달배분범위,1) | L8: =G8*I8*INDEX(배달배분범위,2) | M8: =G8*I8*INDEX(배달배분범위,3) | N8: =SUM(J8:M8) | O8: =J8*INDEX(평균금융일수범위,1)+K8*INDEX(평균금융일수범위,2)+L8*INDEX(평균금융일수범위,3)+M8*INDEX(평균금융일수범위,4) | P8: =IF(SW_방향="A",G8*H8*$B$15,G8*입력!I56) | Q8: =P8*(1-할인율) | R8: =P8*(1-할인율)*O8 | S8: =IF($R$10=0,0,R8/$R$10) | T8: =IF(G8=0,"",ROUND(ROUND(O8,6),SW_자릿수)) | U8: =J8*INDEX(미지급률범위,1)+K8*INDEX(미지급률범위,2)+L8*INDEX(미지급률범위,3)+M8*INDEX(미지급률범위,4) | V8: =J8*INDEX(과지급률범위,1)+K8*INDEX(과지급률범위,2)+L8*INDEX(과지급률범위,3)+M8*INDEX(과지급률범위,4) | W8: =IF(G8=0,"",ROUND((U8-V8)/(1-할인율)*100,6)) | X8: =IF(G8=0,"",ROUND(할인율퍼센트*연일수/ROUND(O8,6),6)) | Y8: =IF(G8=0,"",IF(P8>=5000000,"고액",IF(P8>=2000000,"평범","소액"))) | Z8: =IF(G8=0,"",ROUNDDOWN(S8*1000,0)/10) | AA8: =IF(G8=0,"",S8*100-Z8) | AB8: =IF(G8=0,"",RANK(AA8,$AA$2:$AA$9,0)+COUNTIF($AA$2:AA8,AA8)-1) | AC8: =IF(G8=0,"",Z8+IF(AB8<=$B$11,0.1,0)) | AD8: =입력!J56
A9: =입력!A57 | B9: =입력!B57 | C9: =입력!C57 | D9: =입력!D57 | E9: =입력!E57 | F9: =입력!F57 | G9: =IF(A9<=SW_가맹점수,1,0) | H9: =입력!G57 | I9: =입력!H57 | J9: =G9*(1-I9) | K9: =G9*I9*INDEX(배달배분범위,1) | L9: =G9*I9*INDEX(배달배분범위,2) | M9: =G9*I9*INDEX(배달배분범위,3) | N9: =SUM(J9:M9) | O9: =J9*INDEX(평균금융일수범위,1)+K9*INDEX(평균금융일수범위,2)+L9*INDEX(평균금융일수범위,3)+M9*INDEX(평균금융일수범위,4) | P9: =IF(SW_방향="A",G9*H9*$B$15,G9*입력!I57) | Q9: =P9*(1-할인율) | R9: =P9*(1-할인율)*O9 | S9: =IF($R$10=0,0,R9/$R$10) | T9: =IF(G9=0,"",ROUND(ROUND(O9,6),SW_자릿수)) | U9: =J9*INDEX(미지급률범위,1)+K9*INDEX(미지급률범위,2)+L9*INDEX(미지급률범위,3)+M9*INDEX(미지급률범위,4) | V9: =J9*INDEX(과지급률범위,1)+K9*INDEX(과지급률범위,2)+L9*INDEX(과지급률범위,3)+M9*INDEX(과지급률범위,4) | W9: =IF(G9=0,"",ROUND((U9-V9)/(1-할인율)*100,6)) | X9: =IF(G9=0,"",ROUND(할인율퍼센트*연일수/ROUND(O9,6),6)) | Y9: =IF(G9=0,"",IF(P9>=5000000,"고액",IF(P9>=2000000,"평범","소액"))) | Z9: =IF(G9=0,"",ROUNDDOWN(S9*1000,0)/10) | AA9: =IF(G9=0,"",S9*100-Z9) | AB9: =IF(G9=0,"",RANK(AA9,$AA$2:$AA$9,0)+COUNTIF($AA$2:AA9,AA9)-1) | AC9: =IF(G9=0,"",Z9+IF(AB9<=$B$11,0.1,0)) | AD9: =입력!J57
C10: 합계 | G10: =SUM(G2:G9) | H10: =SUM(H2:H9) | O10: =IF(P10=0,0,SUMPRODUCT(P2:P9,O2:O9)/P10) | P10: =SUM(P2:P9) | Q10: =SUM(Q2:Q9) | R10: =SUM(R2:R9) | S10: =SUM(S2:S9) | T10: =ROUND(ROUND(O10,6),SW_자릿수) | Z10: =SUM(Z2:Z9) | AC10: =SUM(AC2:AC9) | AD10: =COUNTIF(AD2:AD9,"서명 대기")&"건 대기"
A11: 나눠 줄 눈금 수 k (0.1pp) | B11: =ROUND((100-Z10)/0.1,0) | C11: (100 - Σ 비중 내림) / 0.1
A12: 항목 | B12: 값 | C12: 산식
A13: flow 가중 w금융일수 W_flow | B13: =IF(SUMPRODUCT(G2:G9,H2:H9)=0,0,SUMPRODUCT(G2:G9,H2:H9,O2:O9)/SUMPRODUCT(G2:G9,H2:H9)) | C13: Σ(사용 x flow x w금융일수) / Σ(사용 x flow)
A14: 하루 선정산액 합계 (방향 A) | B14: =IF(B13=0,0,투자실행액목표/((1-할인율)*B13)) | C14: 투자실행액 / (1-r) / W_flow
A15: 배율 (방향 A) | B15: =IF(SUMPRODUCT(G2:G9,H2:H9)=0,0,B14/SUMPRODUCT(G2:G9,H2:H9)) | C15: 하루 선정산액 합계 / Σ(사용 x flow)
A16: 하루 선정산액 합계 (적용) | B16: =P10 | C16: Σ 하루 선정산액
A17: 금액가중 W금융일수 | B17: =O10 | C17: Σ(하루선정산액 x w금융일수) / Σ 하루선정산액
A18: 투자실행액 (모집단 산식) | B18: =B16*(1-할인율)*B17 | C18: 합계 x (1-r) x W
A19: 가맹점 수 (적용) | B19: =SUM(G2:G9) | C19: Σ 사용
A20: 가맹점 수 (방향 A 산출) | B20: =IF(가맹점평균=0,0,B16/가맹점평균) | C20: 하루 선정산액 합계 / 가맹점 평균
A21: 곳당 평균 하루 선정산액 | B21: =IF(B19=0,0,B16/B19) | C21: 합계 / 가맹점 수
A22: 순현금 | B22: =순현금 | C22: 입력
A23: 투자자산 | B23: =B18+B22 | C23: 투자실행액 + 순현금
A24: 투자실행액 비중 | B24: =B18/B23 | C24: 투자실행액 / 투자자산
A25: 순현금 비중 | B25: =B22/B23 | C25: 순현금 / 투자자산
A27: 플랫폼 | B27: 로스터 금액가중 구성비 | C27: 대표 구성비 | D27: 차
A28: 카드사 | B28: =IF($P$10=0,0,SUMPRODUCT($P$2:$P$9,J2:J9)/$P$10) | C28: =INDEX(구성비범위,1) | D28: =B28-C28
A29: 배달의민족 | B29: =IF($P$10=0,0,SUMPRODUCT($P$2:$P$9,K2:K9)/$P$10) | C29: =INDEX(구성비범위,2) | D29: =B29-C29
A30: 쿠팡이츠 | B30: =IF($P$10=0,0,SUMPRODUCT($P$2:$P$9,L2:L9)/$P$10) | C30: =INDEX(구성비범위,3) | D30: =B30-C30
A31: 요기요 | B31: =IF($P$10=0,0,SUMPRODUCT($P$2:$P$9,M2:M9)/$P$10) | C31: =INDEX(구성비범위,4) | D31: =B31-C31

Sheet 채권
A1: 번호 | B1: 가맹점 | C1: 플랫폼 | D1: 가맹점# | E1: 플랫폼# | F1: 선정산일 | G1: 정산예정일 | H1: 금융일수 Di | I1: 순지급액 | J1: Ai | K1: 채권매입수수료 | L1: 미지급액 | M1: 과지급액 | N1: 차감액 | O1: 투자수익 Mi | P1: 상환액 Bi | Q1: 미회수 | R1: 만기 도래 | S1: Ai x Di | T1: S표본 | U1: 조회기간
A2: =ROW()-1 | B2: =INDEX(상호범위,D2) | C2: =INDEX(플랫폼명범위,E2) | D2: =MOD(INT((A2-1)/4),8)+1 | E2: =MOD(A2-1,4)+1 | F2: =축시작+INT((A2-1)/32) | G2: =F2+H2 | H2: 1 | I2: =ROUND(INDEX(가맹점!$P$2:$P$9,D2)*INDEX(가맹점!$J$2:$M$9,D2,E2),0) | J2: =ROUND(I2*(1-할인율),0) | K2: =ROUNDDOWN(I2*할인율,0) | L2: =ROUND(I2*INDEX(미지급률범위,E2),0) | M2: =ROUND(I2*INDEX(과지급률범위,E2),0) | N2: =MAX(0,L2-M2) | O2: =K2-N2 | P2: =I2-N2 | Q2: =IF(G2>기준일,1,0) | R2: =IF(G2<=기준일,1,0) | S2: =J2*H2 | T2: =IF(AND(F2>=표본시작,F2<=표본종료),1,0) | U2: =IF(AND(G2>=조회시작,G2<=조회종료),1,0)
A3: =ROW()-1 | B3: =INDEX(상호범위,D3) | C3: =INDEX(플랫폼명범위,E3) | D3: =MOD(INT((A3-1)/4),8)+1 | E3: =MOD(A3-1,4)+1 | F3: =축시작+INT((A3-1)/32) | G3: =F3+H3 | H3: 2 | I3: =ROUND(INDEX(가맹점!$P$2:$P$9,D3)*INDEX(가맹점!$J$2:$M$9,D3,E3),0) | J3: =ROUND(I3*(1-할인율),0) | K3: =ROUNDDOWN(I3*할인율,0) | L3: =ROUND(I3*INDEX(미지급률범위,E3),0) | M3: =ROUND(I3*INDEX(과지급률범위,E3),0) | N3: =MAX(0,L3-M3) | O3: =K3-N3 | P3: =I3-N3 | Q3: =IF(G3>기준일,1,0) | R3: =IF(G3<=기준일,1,0) | S3: =J3*H3 | T3: =IF(AND(F3>=표본시작,F3<=표본종료),1,0) | U3: =IF(AND(G3>=조회시작,G3<=조회종료),1,0)
A4: =ROW()-1 | B4: =INDEX(상호범위,D4) | C4: =INDEX(플랫폼명범위,E4) | D4: =MOD(INT((A4-1)/4),8)+1 | E4: =MOD(A4-1,4)+1 | F4: =축시작+INT((A4-1)/32) | G4: =F4+H4 | H4: 5 | I4: =ROUND(INDEX(가맹점!$P$2:$P$9,D4)*INDEX(가맹점!$J$2:$M$9,D4,E4),0) | J4: =ROUND(I4*(1-할인율),0) | K4: =ROUNDDOWN(I4*할인율,0) | L4: =ROUND(I4*INDEX(미지급률범위,E4),0) | M4: =ROUND(I4*INDEX(과지급률범위,E4),0) | N4: =MAX(0,L4-M4) | O4: =K4-N4 | P4: =I4-N4 | Q4: =IF(G4>기준일,1,0) | R4: =IF(G4<=기준일,1,0) | S4: =J4*H4 | T4: =IF(AND(F4>=표본시작,F4<=표본종료),1,0) | U4: =IF(AND(G4>=조회시작,G4<=조회종료),1,0)
A5: =ROW()-1 | B5: =INDEX(상호범위,D5) | C5: =INDEX(플랫폼명범위,E5) | D5: =MOD(INT((A5-1)/4),8)+1 | E5: =MOD(A5-1,4)+1 | F5: =축시작+INT((A5-1)/32) | G5: =F5+H5 | H5: 12 | I5: =ROUND(INDEX(가맹점!$P$2:$P$9,D5)*INDEX(가맹점!$J$2:$M$9,D5,E5),0) | J5: =ROUND(I5*(1-할인율),0) | K5: =ROUNDDOWN(I5*할인율,0) | L5: =ROUND(I5*INDEX(미지급률범위,E5),0) | M5: =ROUND(I5*INDEX(과지급률범위,E5),0) | N5: =MAX(0,L5-M5) | O5: =K5-N5 | P5: =I5-N5 | Q5: =IF(G5>기준일,1,0) | R5: =IF(G5<=기준일,1,0) | S5: =J5*H5 | T5: =IF(AND(F5>=표본시작,F5<=표본종료),1,0) | U5: =IF(AND(G5>=조회시작,G5<=조회종료),1,0)
A6: =ROW()-1 | B6: =INDEX(상호범위,D6) | C6: =INDEX(플랫폼명범위,E6) | D6: =MOD(INT((A6-1)/4),8)+1 | E6: =MOD(A6-1,4)+1 | F6: =축시작+INT((A6-1)/32) | G6: =F6+H6 | H6: 1 | I6: =ROUND(INDEX(가맹점!$P$2:$P$9,D6)*INDEX(가맹점!$J$2:$M$9,D6,E6),0) | J6: =ROUND(I6*(1-할인율),0) | K6: =ROUNDDOWN(I6*할인율,0) | L6: =ROUND(I6*INDEX(미지급률범위,E6),0) | M6: =ROUND(I6*INDEX(과지급률범위,E6),0) | N6: =MAX(0,L6-M6) | O6: =K6-N6 | P6: =I6-N6 | Q6: =IF(G6>기준일,1,0) | R6: =IF(G6<=기준일,1,0) | S6: =J6*H6 | T6: =IF(AND(F6>=표본시작,F6<=표본종료),1,0) | U6: =IF(AND(G6>=조회시작,G6<=조회종료),1,0)
A7: =ROW()-1 | B7: =INDEX(상호범위,D7) | C7: =INDEX(플랫폼명범위,E7) | D7: =MOD(INT((A7-1)/4),8)+1 | E7: =MOD(A7-1,4)+1 | F7: =축시작+INT((A7-1)/32) | G7: =F7+H7 | H7: 2 | I7: =ROUND(INDEX(가맹점!$P$2:$P$9,D7)*INDEX(가맹점!$J$2:$M$9,D7,E7),0) | J7: =ROUND(I7*(1-할인율),0) | K7: =ROUNDDOWN(I7*할인율,0) | L7: =ROUND(I7*INDEX(미지급률범위,E7),0) | M7: =ROUND(I7*INDEX(과지급률범위,E7),0) | N7: =MAX(0,L7-M7) | O7: =K7-N7 | P7: =I7-N7 | Q7: =IF(G7>기준일,1,0) | R7: =IF(G7<=기준일,1,0) | S7: =J7*H7 | T7: =IF(AND(F7>=표본시작,F7<=표본종료),1,0) | U7: =IF(AND(G7>=조회시작,G7<=조회종료),1,0)
A8: =ROW()-1 | B8: =INDEX(상호범위,D8) | C8: =INDEX(플랫폼명범위,E8) | D8: =MOD(INT((A8-1)/4),8)+1 | E8: =MOD(A8-1,4)+1 | F8: =축시작+INT((A8-1)/32) | G8: =F8+H8 | H8: 5 | I8: =ROUND(INDEX(가맹점!$P$2:$P$9,D8)*INDEX(가맹점!$J$2:$M$9,D8,E8),0) | J8: =ROUND(I8*(1-할인율),0) | K8: =ROUNDDOWN(I8*할인율,0) | L8: =ROUND(I8*INDEX(미지급률범위,E8),0) | M8: =ROUND(I8*INDEX(과지급률범위,E8),0) | N8: =MAX(0,L8-M8) | O8: =K8-N8 | P8: =I8-N8 | Q8: =IF(G8>기준일,1,0) | R8: =IF(G8<=기준일,1,0) | S8: =J8*H8 | T8: =IF(AND(F8>=표본시작,F8<=표본종료),1,0) | U8: =IF(AND(G8>=조회시작,G8<=조회종료),1,0)
A9: =ROW()-1 | B9: =INDEX(상호범위,D9) | C9: =INDEX(플랫폼명범위,E9) | D9: =MOD(INT((A9-1)/4),8)+1 | E9: =MOD(A9-1,4)+1 | F9: =축시작+INT((A9-1)/32) | G9: =F9+H9 | H9: 12 | I9: =ROUND(INDEX(가맹점!$P$2:$P$9,D9)*INDEX(가맹점!$J$2:$M$9,D9,E9),0) | J9: =ROUND(I9*(1-할인율),0) | K9: =ROUNDDOWN(I9*할인율,0) | L9: =ROUND(I9*INDEX(미지급률범위,E9),0) | M9: =ROUND(I9*INDEX(과지급률범위,E9),0) | N9: =MAX(0,L9-M9) | O9: =K9-N9 | P9: =I9-N9 | Q9: =IF(G9>기준일,1,0) | R9: =IF(G9<=기준일,1,0) | S9: =J9*H9 | T9: =IF(AND(F9>=표본시작,F9<=표본종료),1,0) | U9: =IF(AND(G9>=조회시작,G9<=조회종료),1,0)
A10: =ROW()-1 | B10: =INDEX(상호범위,D10) | C10: =INDEX(플랫폼명범위,E10) | D10: =MOD(INT((A10-1)/4),8)+1 | E10: =MOD(A10-1,4)+1 | F10: =축시작+INT((A10-1)/32) | G10: =F10+H10 | H10: 3 | I10: =ROUND(INDEX(가맹점!$P$2:$P$9,D10)*INDEX(가맹점!$J$2:$M$9,D10,E10),0) | J10: =ROUND(I10*(1-할인율),0) | K10: =ROUNDDOWN(I10*할인율,0) | L10: =ROUND(I10*INDEX(미지급률범위,E10),0) | M10: =ROUND(I10*INDEX(과지급률범위,E10),0) | N10: =MAX(0,L10-M10) | O10: =K10-N10 | P10: =I10-N10 | Q10: =IF(G10>기준일,1,0) | R10: =IF(G10<=기준일,1,0) | S10: =J10*H10 | T10: =IF(AND(F10>=표본시작,F10<=표본종료),1,0) | U10: =IF(AND(G10>=조회시작,G10<=조회종료),1,0)
A11: =ROW()-1 | B11: =INDEX(상호범위,D11) | C11: =INDEX(플랫폼명범위,E11) | D11: =MOD(INT((A11-1)/4),8)+1 | E11: =MOD(A11-1,4)+1 | F11: =축시작+INT((A11-1)/32) | G11: =F11+H11 | H11: 2 | I11: =ROUND(INDEX(가맹점!$P$2:$P$9,D11)*INDEX(가맹점!$J$2:$M$9,D11,E11),0) | J11: =ROUND(I11*(1-할인율),0) | K11: =ROUNDDOWN(I11*할인율,0) | L11: =ROUND(I11*INDEX(미지급률범위,E11),0) | M11: =ROUND(I11*INDEX(과지급률범위,E11),0) | N11: =MAX(0,L11-M11) | O11: =K11-N11 | P11: =I11-N11 | Q11: =IF(G11>기준일,1,0) | R11: =IF(G11<=기준일,1,0) | S11: =J11*H11 | T11: =IF(AND(F11>=표본시작,F11<=표본종료),1,0) | U11: =IF(AND(G11>=조회시작,G11<=조회종료),1,0)
A12: =ROW()-1 | B12: =INDEX(상호범위,D12) | C12: =INDEX(플랫폼명범위,E12) | D12: =MOD(INT((A12-1)/4),8)+1 | E12: =MOD(A12-1,4)+1 | F12: =축시작+INT((A12-1)/32) | G12: =F12+H12 | H12: 5 | I12: =ROUND(INDEX(가맹점!$P$2:$P$9,D12)*INDEX(가맹점!$J$2:$M$9,D12,E12),0) | J12: =ROUND(I12*(1-할인율),0) | K12: =ROUNDDOWN(I12*할인율,0) | L12: =ROUND(I12*INDEX(미지급률범위,E12),0) | M12: =ROUND(I12*INDEX(과지급률범위,E12),0) | N12: =MAX(0,L12-M12) | O12: =K12-N12 | P12: =I12-N12 | Q12: =IF(G12>기준일,1,0) | R12: =IF(G12<=기준일,1,0) | S12: =J12*H12 | T12: =IF(AND(F12>=표본시작,F12<=표본종료),1,0) | U12: =IF(AND(G12>=조회시작,G12<=조회종료),1,0)
A13: =ROW()-1 | B13: =INDEX(상호범위,D13) | C13: =INDEX(플랫폼명범위,E13) | D13: =MOD(INT((A13-1)/4),8)+1 | E13: =MOD(A13-1,4)+1 | F13: =축시작+INT((A13-1)/32) | G13: =F13+H13 | H13: 9 | I13: =ROUND(INDEX(가맹점!$P$2:$P$9,D13)*INDEX(가맹점!$J$2:$M$9,D13,E13),0) | J13: =ROUND(I13*(1-할인율),0) | K13: =ROUNDDOWN(I13*할인율,0) | L13: =ROUND(I13*INDEX(미지급률범위,E13),0) | M13: =ROUND(I13*INDEX(과지급률범위,E13),0) | N13: =MAX(0,L13-M13) | O13: =K13-N13 | P13: =I13-N13 | Q13: =IF(G13>기준일,1,0) | R13: =IF(G13<=기준일,1,0) | S13: =J13*H13 | T13: =IF(AND(F13>=표본시작,F13<=표본종료),1,0) | U13: =IF(AND(G13>=조회시작,G13<=조회종료),1,0)
... A1281: =ROW()-1 | B1281: =INDEX(상호범위,D1281) | C1281: =INDEX(플랫폼명범위,E1281) | D1281: =MOD(INT((A1281-1)/4),8)+1 | E1281: =MOD(A1281-1,4)+1 | F1281: =축시작+INT((A1281-1)/32) | G1281: =F1281+H1281 | H1281: 5 | I1281: =ROUND(INDEX(가맹점!$P$2:$P$9,D1281)*INDEX(가맹점!$J$2:$M$9,D1281,E1281),0) | J1281: =ROUND(I1281*(1-할인율),0) | K1281: =ROUNDDOWN(I1281*할인율,0) | L1281: =ROUND(I1281*INDEX(미지급률범위,E1281),0) | M1281: =ROUND(I1281*INDEX(과지급률범위,E1281),0) | N1281: =MAX(0,L1281-M1281) | O1281: =K1281-N1281 | P1281: =I1281-N1281 | Q1281: =IF(G1281>기준일,1,0) | R1281: =IF(G1281<=기준일,1,0) | S1281: =J1281*H1281 | T1281: =IF(AND(F1281>=표본시작,F1281<=표본종료),1,0) | U1281: =IF(AND(G1281>=조회시작,G1281<=조회종료),1,0)

Sheet 일별
A1: 정산예정일 | B1: 건수 | C1: B(d-1) 상환액 | D1: A(d-1) 투자실행금 | E1: M(d-1) 투자수익 (화면 표시값) | F1: M(d-1) 투자수익(차감 제외 · 참고) | G1: MR(d-1) 투자수익율(%) | H1: wD(d-1) W금융일수 | I1: ty수익율(%) | J1: EC 순현금 (미확정) | K1: Σ(Ai x Di) | L1: 부족액 차감 | M1: 차감/수수료(%) | N1: 미확정 — EC 는 전일자 마감시점(자정) 잔액. 일별 EC 원장이 없어 J2:J28 27칸 전부 조회시점 순현금(입력 C8)을 그대로 놓았다. 그래서 PEC 는 순현금 x 조회 일수다.
A2: =일별시작+0 | B2: =COUNTIFS(채권!$G$2:$G$1281,$A2) | C2: =SUMIFS(채권!$P$2:$P$1281,채권!$G$2:$G$1281,$A2) | D2: =SUMIFS(채권!$J$2:$J$1281,채권!$G$2:$G$1281,$A2) | E2: =SUMIFS(채권!$O$2:$O$1281,채권!$G$2:$G$1281,$A2) | F2: =SUMIFS(채권!$K$2:$K$1281,채권!$G$2:$G$1281,$A2) | G2: =IF(D2=0,0,ROUND(E2/D2*100,6)) | H2: =IF(D2=0,0,ROUND(K2/D2,6)) | I2: =IF(H2=0,0,ROUND(G2*연일수/H2,6)) | J2: =순현금 | K2: =SUMIFS(채권!$S$2:$S$1281,채권!$G$2:$G$1281,$A2) | L2: =SUMIFS(채권!$N$2:$N$1281,채권!$G$2:$G$1281,$A2) | M2: =IF(F2=0,0,L2/F2*100)
A3: =일별시작+1 | B3: =COUNTIFS(채권!$G$2:$G$1281,$A3) | C3: =SUMIFS(채권!$P$2:$P$1281,채권!$G$2:$G$1281,$A3) | D3: =SUMIFS(채권!$J$2:$J$1281,채권!$G$2:$G$1281,$A3) | E3: =SUMIFS(채권!$O$2:$O$1281,채권!$G$2:$G$1281,$A3) | F3: =SUMIFS(채권!$K$2:$K$1281,채권!$G$2:$G$1281,$A3) | G3: =IF(D3=0,0,ROUND(E3/D3*100,6)) | H3: =IF(D3=0,0,ROUND(K3/D3,6)) | I3: =IF(H3=0,0,ROUND(G3*연일수/H3,6)) | J3: =순현금 | K3: =SUMIFS(채권!$S$2:$S$1281,채권!$G$2:$G$1281,$A3) | L3: =SUMIFS(채권!$N$2:$N$1281,채권!$G$2:$G$1281,$A3) | M3: =IF(F3=0,0,L3/F3*100)
A4: =일별시작+2 | B4: =COUNTIFS(채권!$G$2:$G$1281,$A4) | C4: =SUMIFS(채권!$P$2:$P$1281,채권!$G$2:$G$1281,$A4) | D4: =SUMIFS(채권!$J$2:$J$1281,채권!$G$2:$G$1281,$A4) | E4: =SUMIFS(채권!$O$2:$O$1281,채권!$G$2:$G$1281,$A4) | F4: =SUMIFS(채권!$K$2:$K$1281,채권!$G$2:$G$1281,$A4) | G4: =IF(D4=0,0,ROUND(E4/D4*100,6)) | H4: =IF(D4=0,0,ROUND(K4/D4,6)) | I4: =IF(H4=0,0,ROUND(G4*연일수/H4,6)) | J4: =순현금 | K4: =SUMIFS(채권!$S$2:$S$1281,채권!$G$2:$G$1281,$A4) | L4: =SUMIFS(채권!$N$2:$N$1281,채권!$G$2:$G$1281,$A4) | M4: =IF(F4=0,0,L4/F4*100)
A5: =일별시작+3 | B5: =COUNTIFS(채권!$G$2:$G$1281,$A5) | C5: =SUMIFS(채권!$P$2:$P$1281,채권!$G$2:$G$1281,$A5) | D5: =SUMIFS(채권!$J$2:$J$1281,채권!$G$2:$G$1281,$A5) | E5: =SUMIFS(채권!$O$2:$O$1281,채권!$G$2:$G$1281,$A5) | F5: =SUMIFS(채권!$K$2:$K$1281,채권!$G$2:$G$1281,$A5) | G5: =IF(D5=0,0,ROUND(E5/D5*100,6)) | H5: =IF(D5=0,0,ROUND(K5/D5,6)) | I5: =IF(H5=0,0,ROUND(G5*연일수/H5,6)) | J5: =순현금 | K5: =SUMIFS(채권!$S$2:$S$1281,채권!$G$2:$G$1281,$A5) | L5: =SUMIFS(채권!$N$2:$N$1281,채권!$G$2:$G$1281,$A5) | M5: =IF(F5=0,0,L5/F5*100)
A6: =일별시작+4 | B6: =COUNTIFS(채권!$G$2:$G$1281,$A6) | C6: =SUMIFS(채권!$P$2:$P$1281,채권!$G$2:$G$1281,$A6) | D6: =SUMIFS(채권!$J$2:$J$1281,채권!$G$2:$G$1281,$A6) | E6: =SUMIFS(채권!$O$2:$O$1281,채권!$G$2:$G$1281,$A6) | F6: =SUMIFS(채권!$K$2:$K$1281,채권!$G$2:$G$1281,$A6) | G6: =IF(D6=0,0,ROUND(E6/D6*100,6)) | H6: =IF(D6=0,0,ROUND(K6/D6,6)) | I6: =IF(H6=0,0,ROUND(G6*연일수/H6,6)) | J6: =순현금 | K6: =SUMIFS(채권!$S$2:$S$1281,채권!$G$2:$G$1281,$A6) | L6: =SUMIFS(채권!$N$2:$N$1281,채권!$G$2:$G$1281,$A6) | M6: =IF(F6=0,0,L6/F6*100)
A7: =일별시작+5 | B7: =COUNTIFS(채권!$G$2:$G$1281,$A7) | C7: =SUMIFS(채권!$P$2:$P$1281,채권!$G$2:$G$1281,$A7) | D7: =SUMIFS(채권!$J$2:$J$1281,채권!$G$2:$G$1281,$A7) | E7: =SUMIFS(채권!$O$2:$O$1281,채권!$G$2:$G$1281,$A7) | F7: =SUMIFS(채권!$K$2:$K$1281,채권!$G$2:$G$1281,$A7) | G7: =IF(D7=0,0,ROUND(E7/D7*100,6)) | H7: =IF(D7=0,0,ROUND(K7/D7,6)) | I7: =IF(H7=0,0,ROUND(G7*연일수/H7,6)) | J7: =순현금 | K7: =SUMIFS(채권!$S$2:$S$1281,채권!$G$2:$G$1281,$A7) | L7: =SUMIFS(채권!$N$2:$N$1281,채권!$G$2:$G$1281,$A7) | M7: =IF(F7=0,0,L7/F7*100)
A8: =일별시작+6 | B8: =COUNTIFS(채권!$G$2:$G$1281,$A8) | C8: =SUMIFS(채권!$P$2:$P$1281,채권!$G$2:$G$1281,$A8) | D8: =SUMIFS(채권!$J$2:$J$1281,채권!$G$2:$G$1281,$A8) | E8: =SUMIFS(채권!$O$2:$O$1281,채권!$G$2:$G$1281,$A8) | F8: =SUMIFS(채권!$K$2:$K$1281,채권!$G$2:$G$1281,$A8) | G8: =IF(D8=0,0,ROUND(E8/D8*100,6)) | H8: =IF(D8=0,0,ROUND(K8/D8,6)) | I8: =IF(H8=0,0,ROUND(G8*연일수/H8,6)) | J8: =순현금 | K8: =SUMIFS(채권!$S$2:$S$1281,채권!$G$2:$G$1281,$A8) | L8: =SUMIFS(채권!$N$2:$N$1281,채권!$G$2:$G$1281,$A8) | M8: =IF(F8=0,0,L8/F8*100)
A9: =일별시작+7 | B9: =COUNTIFS(채권!$G$2:$G$1281,$A9) | C9: =SUMIFS(채권!$P$2:$P$1281,채권!$G$2:$G$1281,$A9) | D9: =SUMIFS(채권!$J$2:$J$1281,채권!$G$2:$G$1281,$A9) | E9: =SUMIFS(채권!$O$2:$O$1281,채권!$G$2:$G$1281,$A9) | F9: =SUMIFS(채권!$K$2:$K$1281,채권!$G$2:$G$1281,$A9) | G9: =IF(D9=0,0,ROUND(E9/D9*100,6)) | H9: =IF(D9=0,0,ROUND(K9/D9,6)) | I9: =IF(H9=0,0,ROUND(G9*연일수/H9,6)) | J9: =순현금 | K9: =SUMIFS(채권!$S$2:$S$1281,채권!$G$2:$G$1281,$A9) | L9: =SUMIFS(채권!$N$2:$N$1281,채권!$G$2:$G$1281,$A9) | M9: =IF(F9=0,0,L9/F9*100)
A10: =일별시작+8 | B10: =COUNTIFS(채권!$G$2:$G$1281,$A10) | C10: =SUMIFS(채권!$P$2:$P$1281,채권!$G$2:$G$1281,$A10) | D10: =SUMIFS(채권!$J$2:$J$1281,채권!$G$2:$G$1281,$A10) | E10: =SUMIFS(채권!$O$2:$O$1281,채권!$G$2:$G$1281,$A10) | F10: =SUMIFS(채권!$K$2:$K$1281,채권!$G$2:$G$1281,$A10) | G10: =IF(D10=0,0,ROUND(E10/D10*100,6)) | H10: =IF(D10=0,0,ROUND(K10/D10,6)) | I10: =IF(H10=0,0,ROUND(G10*연일수/H10,6)) | J10: =순현금 | K10: =SUMIFS(채권!$S$2:$S$1281,채권!$G$2:$G$1281,$A10) | L10: =SUMIFS(채권!$N$2:$N$1281,채권!$G$2:$G$1281,$A10) | M10: =IF(F10=0,0,L10/F10*100)
A11: =일별시작+9 | B11: =COUNTIFS(채권!$G$2:$G$1281,$A11) | C11: =SUMIFS(채권!$P$2:$P$1281,채권!$G$2:$G$1281,$A11) | D11: =SUMIFS(채권!$J$2:$J$1281,채권!$G$2:$G$1281,$A11) | E11: =SUMIFS(채권!$O$2:$O$1281,채권!$G$2:$G$1281,$A11) | F11: =SUMIFS(채권!$K$2:$K$1281,채권!$G$2:$G$1281,$A11) | G11: =IF(D11=0,0,ROUND(E11/D11*100,6)) | H11: =IF(D11=0,0,ROUND(K11/D11,6)) | I11: =IF(H11=0,0,ROUND(G11*연일수/H11,6)) | J11: =순현금 | K11: =SUMIFS(채권!$S$2:$S$1281,채권!$G$2:$G$1281,$A11) | L11: =SUMIFS(채권!$N$2:$N$1281,채권!$G$2:$G$1281,$A11) | M11: =IF(F11=0,0,L11/F11*100)
A12: =일별시작+10 | B12: =COUNTIFS(채권!$G$2:$G$1281,$A12) | C12: =SUMIFS(채권!$P$2:$P$1281,채권!$G$2:$G$1281,$A12) | D12: =SUMIFS(채권!$J$2:$J$1281,채권!$G$2:$G$1281,$A12) | E12: =SUMIFS(채권!$O$2:$O$1281,채권!$G$2:$G$1281,$A12) | F12: =SUMIFS(채권!$K$2:$K$1281,채권!$G$2:$G$1281,$A12) | G12: =IF(D12=0,0,ROUND(E12/D12*100,6)) | H12: =IF(D12=0,0,ROUND(K12/D12,6)) | I12: =IF(H12=0,0,ROUND(G12*연일수/H12,6)) | J12: =순현금 | K12: =SUMIFS(채권!$S$2:$S$1281,채권!$G$2:$G$1281,$A12) | L12: =SUMIFS(채권!$N$2:$N$1281,채권!$G$2:$G$1281,$A12) | M12: =IF(F12=0,0,L12/F12*100)
A13: =일별시작+11 | B13: =COUNTIFS(채권!$G$2:$G$1281,$A13) | C13: =SUMIFS(채권!$P$2:$P$1281,채권!$G$2:$G$1281,$A13) | D13: =SUMIFS(채권!$J$2:$J$1281,채권!$G$2:$G$1281,$A13) | E13: =SUMIFS(채권!$O$2:$O$1281,채권!$G$2:$G$1281,$A13) | F13: =SUMIFS(채권!$K$2:$K$1281,채권!$G$2:$G$1281,$A13) | G13: =IF(D13=0,0,ROUND(E13/D13*100,6)) | H13: =IF(D13=0,0,ROUND(K13/D13,6)) | I13: =IF(H13=0,0,ROUND(G13*연일수/H13,6)) | J13: =순현금 | K13: =SUMIFS(채권!$S$2:$S$1281,채권!$G$2:$G$1281,$A13) | L13: =SUMIFS(채권!$N$2:$N$1281,채권!$G$2:$G$1281,$A13) | M13: =IF(F13=0,0,L13/F13*100)
A14: =일별시작+12 | B14: =COUNTIFS(채권!$G$2:$G$1281,$A14) | C14: =SUMIFS(채권!$P$2:$P$1281,채권!$G$2:$G$1281,$A14) | D14: =SUMIFS(채권!$J$2:$J$1281,채권!$G$2:$G$1281,$A14) | E14: =SUMIFS(채권!$O$2:$O$1281,채권!$G$2:$G$1281,$A14) | F14: =SUMIFS(채권!$K$2:$K$1281,채권!$G$2:$G$1281,$A14) | G14: =IF(D14=0,0,ROUND(E14/D14*100,6)) | H14: =IF(D14=0,0,ROUND(K14/D14,6)) | I14: =IF(H14=0,0,ROUND(G14*연일수/H14,6)) | J14: =순현금 | K14: =SUMIFS(채권!$S$2:$S$1281,채권!$G$2:$G$1281,$A14) | L14: =SUMIFS(채권!$N$2:$N$1281,채권!$G$2:$G$1281,$A14) | M14: =IF(F14=0,0,L14/F14*100)
A15: =일별시작+13 | B15: =COUNTIFS(채권!$G$2:$G$1281,$A15) | C15: =SUMIFS(채권!$P$2:$P$1281,채권!$G$2:$G$1281,$A15) | D15: =SUMIFS(채권!$J$2:$J$1281,채권!$G$2:$G$1281,$A15) | E15: =SUMIFS(채권!$O$2:$O$1281,채권!$G$2:$G$1281,$A15) | F15: =SUMIFS(채권!$K$2:$K$1281,채권!$G$2:$G$1281,$A15) | G15: =IF(D15=0,0,ROUND(E15/D15*100,6)) | H15: =IF(D15=0,0,ROUND(K15/D15,6)) | I15: =IF(H15=0,0,ROUND(G15*연일수/H15,6)) | J15: =순현금 | K15: =SUMIFS(채권!$S$2:$S$1281,채권!$G$2:$G$1281,$A15) | L15: =SUMIFS(채권!$N$2:$N$1281,채권!$G$2:$G$1281,$A15) | M15: =IF(F15=0,0,L15/F15*100)
A16: =일별시작+14 | B16: =COUNTIFS(채권!$G$2:$G$1281,$A16) | C16: =SUMIFS(채권!$P$2:$P$1281,채권!$G$2:$G$1281,$A16) | D16: =SUMIFS(채권!$J$2:$J$1281,채권!$G$2:$G$1281,$A16) | E16: =SUMIFS(채권!$O$2:$O$1281,채권!$G$2:$G$1281,$A16) | F16: =SUMIFS(채권!$K$2:$K$1281,채권!$G$2:$G$1281,$A16) | G16: =IF(D16=0,0,ROUND(E16/D16*100,6)) | H16: =IF(D16=0,0,ROUND(K16/D16,6)) | I16: =IF(H16=0,0,ROUND(G16*연일수/H16,6)) | J16: =순현금 | K16: =SUMIFS(채권!$S$2:$S$1281,채권!$G$2:$G$1281,$A16) | L16: =SUMIFS(채권!$N$2:$N$1281,채권!$G$2:$G$1281,$A16) | M16: =IF(F16=0,0,L16/F16*100)
A17: =일별시작+15 | B17: =COUNTIFS(채권!$G$2:$G$1281,$A17) | C17: =SUMIFS(채권!$P$2:$P$1281,채권!$G$2:$G$1281,$A17) | D17: =SUMIFS(채권!$J$2:$J$1281,채권!$G$2:$G$1281,$A17) | E17: =SUMIFS(채권!$O$2:$O$1281,채권!$G$2:$G$1281,$A17) | F17: =SUMIFS(채권!$K$2:$K$1281,채권!$G$2:$G$1281,$A17) | G17: =IF(D17=0,0,ROUND(E17/D17*100,6)) | H17: =IF(D17=0,0,ROUND(K17/D17,6)) | I17: =IF(H17=0,0,ROUND(G17*연일수/H17,6)) | J17: =순현금 | K17: =SUMIFS(채권!$S$2:$S$1281,채권!$G$2:$G$1281,$A17) | L17: =SUMIFS(채권!$N$2:$N$1281,채권!$G$2:$G$1281,$A17) | M17: =IF(F17=0,0,L17/F17*100)
A18: =일별시작+16 | B18: =COUNTIFS(채권!$G$2:$G$1281,$A18) | C18: =SUMIFS(채권!$P$2:$P$1281,채권!$G$2:$G$1281,$A18) | D18: =SUMIFS(채권!$J$2:$J$1281,채권!$G$2:$G$1281,$A18) | E18: =SUMIFS(채권!$O$2:$O$1281,채권!$G$2:$G$1281,$A18) | F18: =SUMIFS(채권!$K$2:$K$1281,채권!$G$2:$G$1281,$A18) | G18: =IF(D18=0,0,ROUND(E18/D18*100,6)) | H18: =IF(D18=0,0,ROUND(K18/D18,6)) | I18: =IF(H18=0,0,ROUND(G18*연일수/H18,6)) | J18: =순현금 | K18: =SUMIFS(채권!$S$2:$S$1281,채권!$G$2:$G$1281,$A18) | L18: =SUMIFS(채권!$N$2:$N$1281,채권!$G$2:$G$1281,$A18) | M18: =IF(F18=0,0,L18/F18*100)
A19: =일별시작+17 | B19: =COUNTIFS(채권!$G$2:$G$1281,$A19) | C19: =SUMIFS(채권!$P$2:$P$1281,채권!$G$2:$G$1281,$A19) | D19: =SUMIFS(채권!$J$2:$J$1281,채권!$G$2:$G$1281,$A19) | E19: =SUMIFS(채권!$O$2:$O$1281,채권!$G$2:$G$1281,$A19) | F19: =SUMIFS(채권!$K$2:$K$1281,채권!$G$2:$G$1281,$A19) | G19: =IF(D19=0,0,ROUND(E19/D19*100,6)) | H19: =IF(D19=0,0,ROUND(K19/D19,6)) | I19: =IF(H19=0,0,ROUND(G19*연일수/H19,6)) | J19: =순현금 | K19: =SUMIFS(채권!$S$2:$S$1281,채권!$G$2:$G$1281,$A19) | L19: =SUMIFS(채권!$N$2:$N$1281,채권!$G$2:$G$1281,$A19) | M19: =IF(F19=0,0,L19/F19*100)
A20: =일별시작+18 | B20: =COUNTIFS(채권!$G$2:$G$1281,$A20) | C20: =SUMIFS(채권!$P$2:$P$1281,채권!$G$2:$G$1281,$A20) | D20: =SUMIFS(채권!$J$2:$J$1281,채권!$G$2:$G$1281,$A20) | E20: =SUMIFS(채권!$O$2:$O$1281,채권!$G$2:$G$1281,$A20) | F20: =SUMIFS(채권!$K$2:$K$1281,채권!$G$2:$G$1281,$A20) | G20: =IF(D20=0,0,ROUND(E20/D20*100,6)) | H20: =IF(D20=0,0,ROUND(K20/D20,6)) | I20: =IF(H20=0,0,ROUND(G20*연일수/H20,6)) | J20: =순현금 | K20: =SUMIFS(채권!$S$2:$S$1281,채권!$G$2:$G$1281,$A20) | L20: =SUMIFS(채권!$N$2:$N$1281,채권!$G$2:$G$1281,$A20) | M20: =IF(F20=0,0,L20/F20*100)
A21: =일별시작+19 | B21: =COUNTIFS(채권!$G$2:$G$1281,$A21) | C21: =SUMIFS(채권!$P$2:$P$1281,채권!$G$2:$G$1281,$A21) | D21: =SUMIFS(채권!$J$2:$J$1281,채권!$G$2:$G$1281,$A21) | E21: =SUMIFS(채권!$O$2:$O$1281,채권!$G$2:$G$1281,$A21) | F21: =SUMIFS(채권!$K$2:$K$1281,채권!$G$2:$G$1281,$A21) | G21: =IF(D21=0,0,ROUND(E21/D21*100,6)) | H21: =IF(D21=0,0,ROUND(K21/D21,6)) | I21: =IF(H21=0,0,ROUND(G21*연일수/H21,6)) | J21: =순현금 | K21: =SUMIFS(채권!$S$2:$S$1281,채권!$G$2:$G$1281,$A21) | L21: =SUMIFS(채권!$N$2:$N$1281,채권!$G$2:$G$1281,$A21) | M21: =IF(F21=0,0,L21/F21*100)
A22: =일별시작+20 | B22: =COUNTIFS(채권!$G$2:$G$1281,$A22) | C22: =SUMIFS(채권!$P$2:$P$1281,채권!$G$2:$G$1281,$A22) | D22: =SUMIFS(채권!$J$2:$J$1281,채권!$G$2:$G$1281,$A22) | E22: =SUMIFS(채권!$O$2:$O$1281,채권!$G$2:$G$1281,$A22) | F22: =SUMIFS(채권!$K$2:$K$1281,채권!$G$2:$G$1281,$A22) | G22: =IF(D22=0,0,ROUND(E22/D22*100,6)) | H22: =IF(D22=0,0,ROUND(K22/D22,6)) | I22: =IF(H22=0,0,ROUND(G22*연일수/H22,6)) | J22: =순현금 | K22: =SUMIFS(채권!$S$2:$S$1281,채권!$G$2:$G$1281,$A22) | L22: =SUMIFS(채권!$N$2:$N$1281,채권!$G$2:$G$1281,$A22) | M22: =IF(F22=0,0,L22/F22*100)
A23: =일별시작+21 | B23: =COUNTIFS(채권!$G$2:$G$1281,$A23) | C23: =SUMIFS(채권!$P$2:$P$1281,채권!$G$2:$G$1281,$A23) | D23: =SUMIFS(채권!$J$2:$J$1281,채권!$G$2:$G$1281,$A23) | E23: =SUMIFS(채권!$O$2:$O$1281,채권!$G$2:$G$1281,$A23) | F23: =SUMIFS(채권!$K$2:$K$1281,채권!$G$2:$G$1281,$A23) | G23: =IF(D23=0,0,ROUND(E23/D23*100,6)) | H23: =IF(D23=0,0,ROUND(K23/D23,6)) | I23: =IF(H23=0,0,ROUND(G23*연일수/H23,6)) | J23: =순현금 | K23: =SUMIFS(채권!$S$2:$S$1281,채권!$G$2:$G$1281,$A23) | L23: =SUMIFS(채권!$N$2:$N$1281,채권!$G$2:$G$1281,$A23) | M23: =IF(F23=0,0,L23/F23*100)
A24: =일별시작+22 | B24: =COUNTIFS(채권!$G$2:$G$1281,$A24) | C24: =SUMIFS(채권!$P$2:$P$1281,채권!$G$2:$G$1281,$A24) | D24: =SUMIFS(채권!$J$2:$J$1281,채권!$G$2:$G$1281,$A24) | E24: =SUMIFS(채권!$O$2:$O$1281,채권!$G$2:$G$1281,$A24) | F24: =SUMIFS(채권!$K$2:$K$1281,채권!$G$2:$G$1281,$A24) | G24: =IF(D24=0,0,ROUND(E24/D24*100,6)) | H24: =IF(D24=0,0,ROUND(K24/D24,6)) | I24: =IF(H24=0,0,ROUND(G24*연일수/H24,6)) | J24: =순현금 | K24: =SUMIFS(채권!$S$2:$S$1281,채권!$G$2:$G$1281,$A24) | L24: =SUMIFS(채권!$N$2:$N$1281,채권!$G$2:$G$1281,$A24) | M24: =IF(F24=0,0,L24/F24*100)
A25: =일별시작+23 | B25: =COUNTIFS(채권!$G$2:$G$1281,$A25) | C25: =SUMIFS(채권!$P$2:$P$1281,채권!$G$2:$G$1281,$A25) | D25: =SUMIFS(채권!$J$2:$J$1281,채권!$G$2:$G$1281,$A25) | E25: =SUMIFS(채권!$O$2:$O$1281,채권!$G$2:$G$1281,$A25) | F25: =SUMIFS(채권!$K$2:$K$1281,채권!$G$2:$G$1281,$A25) | G25: =IF(D25=0,0,ROUND(E25/D25*100,6)) | H25: =IF(D25=0,0,ROUND(K25/D25,6)) | I25: =IF(H25=0,0,ROUND(G25*연일수/H25,6)) | J25: =순현금 | K25: =SUMIFS(채권!$S$2:$S$1281,채권!$G$2:$G$1281,$A25) | L25: =SUMIFS(채권!$N$2:$N$1281,채권!$G$2:$G$1281,$A25) | M25: =IF(F25=0,0,L25/F25*100)
A26: =일별시작+24 | B26: =COUNTIFS(채권!$G$2:$G$1281,$A26) | C26: =SUMIFS(채권!$P$2:$P$1281,채권!$G$2:$G$1281,$A26) | D26: =SUMIFS(채권!$J$2:$J$1281,채권!$G$2:$G$1281,$A26) | E26: =SUMIFS(채권!$O$2:$O$1281,채권!$G$2:$G$1281,$A26) | F26: =SUMIFS(채권!$K$2:$K$1281,채권!$G$2:$G$1281,$A26) | G26: =IF(D26=0,0,ROUND(E26/D26*100,6)) | H26: =IF(D26=0,0,ROUND(K26/D26,6)) | I26: =IF(H26=0,0,ROUND(G26*연일수/H26,6)) | J26: =순현금 | K26: =SUMIFS(채권!$S$2:$S$1281,채권!$G$2:$G$1281,$A26) | L26: =SUMIFS(채권!$N$2:$N$1281,채권!$G$2:$G$1281,$A26) | M26: =IF(F26=0,0,L26/F26*100)
A27: =일별시작+25 | B27: =COUNTIFS(채권!$G$2:$G$1281,$A27) | C27: =SUMIFS(채권!$P$2:$P$1281,채권!$G$2:$G$1281,$A27) | D27: =SUMIFS(채권!$J$2:$J$1281,채권!$G$2:$G$1281,$A27) | E27: =SUMIFS(채권!$O$2:$O$1281,채권!$G$2:$G$1281,$A27) | F27: =SUMIFS(채권!$K$2:$K$1281,채권!$G$2:$G$1281,$A27) | G27: =IF(D27=0,0,ROUND(E27/D27*100,6)) | H27: =IF(D27=0,0,ROUND(K27/D27,6)) | I27: =IF(H27=0,0,ROUND(G27*연일수/H27,6)) | J27: =순현금 | K27: =SUMIFS(채권!$S$2:$S$1281,채권!$G$2:$G$1281,$A27) | L27: =SUMIFS(채권!$N$2:$N$1281,채권!$G$2:$G$1281,$A27) | M27: =IF(F27=0,0,L27/F27*100)
A28: =일별시작+26 | B28: =COUNTIFS(채권!$G$2:$G$1281,$A28) | C28: =SUMIFS(채권!$P$2:$P$1281,채권!$G$2:$G$1281,$A28) | D28: =SUMIFS(채권!$J$2:$J$1281,채권!$G$2:$G$1281,$A28) | E28: =SUMIFS(채권!$O$2:$O$1281,채권!$G$2:$G$1281,$A28) | F28: =SUMIFS(채권!$K$2:$K$1281,채권!$G$2:$G$1281,$A28) | G28: =IF(D28=0,0,ROUND(E28/D28*100,6)) | H28: =IF(D28=0,0,ROUND(K28/D28,6)) | I28: =IF(H28=0,0,ROUND(G28*연일수/H28,6)) | J28: =순현금 | K28: =SUMIFS(채권!$S$2:$S$1281,채권!$G$2:$G$1281,$A28) | L28: =SUMIFS(채권!$N$2:$N$1281,채권!$G$2:$G$1281,$A28) | M28: =IF(F28=0,0,L28/F28*100)
A29: 합계 | B29: =SUM(B2:B28) | C29: =SUM(C2:C28) | D29: =SUM(D2:D28) | E29: =SUM(E2:E28) | F29: =SUM(F2:F28) | J29: =SUM(J2:J28) | K29: =SUM(K2:K28) | L29: =SUM(L2:L28) | M29: =IF(F29=0,0,L29/F29*100)

Sheet 기간집계
A1: 항목 | B1: 값 | C1: 산식 | D1: 출처 | E1: 화면 반영
A2: 조회기간 시작 | B2: =조회시작 | C2: 입력
A3: 조회기간 종료 | B3: =조회종료 | C3: 입력
A4: 조회 일수 | B4: =조회종료-조회시작+1 | C4: 종료 - 시작 + 1
A5: PA 투자실행금 | B5: =SUMIFS(일별!$D$2:$D$28,일별!$A$2:$A$28,">="&조회시작,일별!$A$2:$A$28,"<="&조회종료) | C5: Σ A(d-1) | D5: ceo_definitions.md [2번] 투자 실행금(PA) | E5: 정본
A6: PM 투자수익 (정의 · 차감 반영) | B6: =SUMIFS(일별!$E$2:$E$28,일별!$A$2:$A$28,">="&조회시작,일별!$A$2:$A$28,"<="&조회종료) | C6: Σ M(d-1) = Σ(수수료 - max(0,미지급-과지급)) | D6: ceo_definitions.md [2번] Mi | E6: 정본
A7: PM 투자수익 (차감 제외) | B7: =SUMIFS(일별!$F$2:$F$28,일별!$A$2:$A$28,">="&조회시작,일별!$A$2:$A$28,"<="&조회종료) | C7: Σ 채권매입수수료 | D7: 현행 daily_ledger.py:298 | E7: 참고
A8: ② 상환액 | B8: =SUMIFS(일별!$C$2:$C$28,일별!$A$2:$A$28,">="&조회시작,일별!$A$2:$A$28,"<="&조회종료) | C8: Σ B(d-1) | D8: ceo_definitions.md [2번] 이미지의 ② | E8: 정본
A9: Σ(Ai x Di) | B9: =SUMIFS(일별!$K$2:$K$28,일별!$A$2:$A$28,">="&조회시작,일별!$A$2:$A$28,"<="&조회종료) | C9: Σ 일별 Σ(Ai x Di)
A10: PMR (정의)(%) | B10: =IF(B5=0,0,ROUND(B6/B5*100,6)) | C10: ROUND(PM / PA x 100, 6) | D10: ceo_definitions.md [2번] PMR | E10: 정본
A11: PMR (차감 제외)(%) | B11: =IF(B5=0,0,ROUND(B7/B5*100,6)) | C11: ROUND(PM(차감 제외) / PA x 100, 6) | E11: 참고
A12: PwD | B12: =IF(B5=0,0,ROUND(B9/B5,6)) | C12: ROUND(Σ(Ai x Di) / PA, 6) | D12: ceo_definitions.md [2번] PwD | E12: 정본
A13: ④ 투자실행금액 대비 ty수익율 (정의) | B13: =IF(B12=0,0,ROUND(B10*연일수/B12,6)) | C13: ROUND(PMR(%) x 365 / PwD, 6) | D13: ceo_definitions.md [2번] 이미지의 ④ | E13: 정본
A14: ④ (차감 제외) | B14: =IF(B12=0,0,ROUND(B11*연일수/B12,6)) | C14: ROUND(PMR(차감 제외)(%) x 365 / PwD, 6) | E14: 참고
A15: PEC 순현금 합 | B15: =SUMIFS(일별!$J$2:$J$28,일별!$A$2:$A$28,">="&조회시작,일별!$A$2:$A$28,"<="&조회종료) | C15: Σ EC | D15: ceo_definitions.md [2번] PEC | E15: 정본
A16: 평균순현금 | C16: 미확정 — 워드에 이름만 있고 정의 없음 | D16: ceo_definitions.md [2번] 첫 줄 | E16: 미확정
A17: ⑤ wPYMR 투자자산 대비 연환산수익률 (정의) | B17: =입력!C19 | C17: 입력 C19 | D17: ceo_definitions.md [2번] 이미지의 ⑤ — 대표 재작성 대기 (A-01) | E17: 미확정
A18: ⑥ 투자실행금액 대비 ty수익율 (정의) | B18: =IF(COUNT(입력!C18)=0,"미확정",B13/입력!C18*연일수/B17) | C18: (④ / ③) x 365 / ⑤ — ③ 은 입력 C18, ⑤ 는 B17 | D18: ceo_definitions.md [2번] 이미지의 ⑥ — 대표 주석 「계산식 다시 확인해볼것」 (TP-66 · F-23) | E18: 미확정
A19: 부족액 차감 합 | B19: =SUMIFS(일별!$L$2:$L$28,일별!$A$2:$A$28,">="&조회시작,일별!$A$2:$A$28,"<="&조회종료) | C19: Σ max(0, 미지급금 - 과지급금) | D19: ceo_definitions.md [2번] Mi | E19: 정본
A20: 차감 / 채권매입수수료(%) | B20: =IF(B7=0,0,B19/B7*100) | C20: 부족액 차감 합 / Σ 수수료
A21: 검산 — 수수료 - 차감 - PM(정의) | B21: =B7-B19-B6 | C21: 0 이면 정의대로다
A22: DM 16:45 (가) 대표 근사식(%) | B22: =(할인율-IF(B5=0,0,B19/B5))*100 | C22: (할인율 - Σ max(0, 미지급금-과지급금) / PA) x 100 | D22: 대표 DM 2026-08-31 16:45
A23: DM 16:45 (나) 원식 PMR(%) | B23: =B10 | C23: PM / PA x 100 — 분모가 투자실행액이라 순지급액 기준보다 1/(1-할인율) 배 | D23: 대표 DM 2026-08-31 16:45
A24: DM 16:45 (나) - (가) (%p) | B24: =B23-B22 | C24: (나) - (가) | D24: 대표 DM 2026-08-31 16:45
A25: DM 16:45 (나) / (가) (배) | B25: =IF(B22=0,0,B23/B22) | C25: (나) / (가) | D25: 대표 DM 2026-08-31 16:45
A26: DM 16:45 1 / (1 - 할인율) (배) | B26: =1/(1-할인율) | C26: 이론 갈림 배수 | D26: 대표 DM 2026-08-31 16:45
A27: DM 16:45 차감합 | B27: =B19 | C27: Σ max(0, 미지급금-과지급금). 0 이면 (가) 가 할인율 그대로다 | D27: 대표 DM 2026-08-31 16:45
A28: DM 16:45 차감합 0 일 때 (가) (%) | B28: =할인율*100 | C28: 할인율 | D28: 대표 DM 2026-08-31 16:45
A29: DM 16:45 차감합 0 일 때 (나) (%) | B29: =할인율/(1-할인율)*100 | C29: 할인율 / (1 - 할인율) — 원식은 분모가 순지급액이 아니라 투자실행액이다 | D29: 대표 DM 2026-08-31 16:45
A31: 항목 | B31: 값 | C31: 산식 | D31: 출처
A32: 대상정산금채권 Σ Ai | B32: =SUM(채권!$J$2:$J$1281) | C32: Σ Ai (선정산일 축 전량)
A33: 대상정산금채권 Σ(Ai x Di) | B33: =SUM(채권!$S$2:$S$1281) | C33: Σ Ai x Di
A34: W금융일수 — 대상정산금채권 전체 | B34: =ROUND(B33/B32,6) | C34: ROUND(Σ(Ai x Di) / Σ Ai, 6) | D34: ceo_definitions.md [1번] w금융일수
A35: 만기 도래분 Σ Ai | B35: =SUMPRODUCT(채권!$J$2:$J$1281,채권!$R$2:$R$1281) | C35: Σ Ai x 도래 | D35: 조어 — 원문 대응 낱말 없음
A36: 만기 도래분 Σ(Ai x Di) | B36: =SUMPRODUCT(채권!$S$2:$S$1281,채권!$R$2:$R$1281) | D36: 조어 — 원문 대응 낱말 없음
A37: W금융일수 — 만기 도래분만 | B37: =IF(B35=0,0,ROUND(B36/B35,6)) | D37: 조어 — 원문 대응 낱말 없음
A38: 미회수 Σ Ai | B38: =SUMPRODUCT(채권!$J$2:$J$1281,채권!$Q$2:$Q$1281) | C38: Σ Ai x 미회수 | D38: ceo_definitions.md [1번] 투자 실행액
A39: 미회수 Σ(Ai x Di) | B39: =SUMPRODUCT(채권!$S$2:$S$1281,채권!$Q$2:$Q$1281)
A40: W금융일수 — 미회수 잔량만 | B40: =IF(B38=0,0,ROUND(B39/B38,6))
A41: W금융일수 raw (스위치 ① 적용) | B41: =IF(SW_모집단="미회수 잔량만",B40,IF(SW_모집단="만기 도래분만",B37,B34)) | C41: 스위치 ①
...

Sheet 가중치 대조
A1: 기준 | B1: 항목 | C1: 값 | H1: 출처
A2: 대표 워드 | B2: w금융일수 산식 | C2: w금융일수 = Σ Ai x Di / Σ Ai | H2: 용어 정의.docx [1번 이미지] 4번 문단
A3: 대표 워드 | B3: Ai 정의 | C3: Ai = ID가 i인 대상정산금채권의 순지급액 x (1- 유동화투자자의 할인율) | H3: 용어 정의.docx [1번 이미지] 5번 문단
A4: 대표 워드 | B4: Di 정의 | C4: Di = ID가 i인 다상정산금채권의 금융일수 | H4: 용어 정의.docx [1번 이미지] 6번 문단
A5: 대표 워드 | B5: 가중치 | C5: 금액(Ai) | H5: Σ Ai x Di / Σ Ai 의 분모가 금액이다
A6: 대표 엑셀 | B6: 플랫폼 비중 근거 | C6: MAU 기반 시장 점유율 | H6: 정산주기.xlsx 비중 시트
A7: 대표 엑셀 | B7: 가중치 | C7: 이용자 수 | H7: 정산주기.xlsx 비중 D4:F4
A8: 대표 엑셀 | B8: MAU 배분 | C8: 배민 2,175 · 쿠팡이츠 1,044 · 요기요 486 → x 배달앱/전체, 카드 = 나머지 | H8: 정산주기.xlsx 비중 D4:H5
A9: 판정 | B9: 어느 쪽을 따르는가 | C9: 워드를 따른다 (2026-08-31 사용자 결정) | H9: “그럼 워드가 맞아 워드 방식으로 다시 계산해”
A11: 플랫폼 | B11: 평균 금융일수 E[d] | C11: (가) 금액 실측 (입력) | D11: (나) 엑셀 MAU | E11: (다) 로스터 금액가중 | F11: (가) - (나) | G11: (다) - (가) | H11: 출처
A12: 카드사 | B12: =INDEX(평균금융일수범위,1) | C12: =INDEX(구성비범위,1) | D12: =1-배달앱비중 | E12: =가맹점!B28 | F12: =C12-D12 | G12: =E12-C12 | H12: 입력 C28 (입력 셀) · 입력 B47 배달앱/전체 · 가맹점 B28
A13: 배달의민족 | B13: =INDEX(평균금융일수범위,2) | C13: =INDEX(구성비범위,2) | D13: =배달앱비중*INDEX(MAU배분범위,1) | E13: =가맹점!B29 | F13: =C13-D13 | G13: =E13-C13 | H13: 입력 C29 (입력 셀) · 입력 C43 · 가맹점 B29
A14: 쿠팡이츠 | B14: =INDEX(평균금융일수범위,3) | C14: =INDEX(구성비범위,3) | D14: =배달앱비중*INDEX(MAU배분범위,2) | E14: =가맹점!B30 | F14: =C14-D14 | G14: =E14-C14 | H14: 입력 C30 (입력 셀) · 입력 C44 · 가맹점 B30
A15: 요기요 | B15: =INDEX(평균금융일수범위,4) | C15: =INDEX(구성비범위,4) | D15: =배달앱비중*INDEX(MAU배분범위,3) | E15: =가맹점!B31 | F15: =C15-D15 | G15: =E15-C15 | H15: 입력 C31 (입력 셀) · 입력 C45 · 가맹점 B31
A16: 합 | C16: =SUM(C12:C15) | D16: =SUM(D12:D15) | E16: =SUM(E12:E15)
A17: W금융일수 | B17: Σ 구성비 x 평균 금융일수 | C17: =ROUND(SUMPRODUCT(평균금융일수범위,C12:C15),6) | D17: =ROUND(SUMPRODUCT(평균금융일수범위,D12:D15),6) | E17: =ROUND(SUMPRODUCT(평균금융일수범위,E12:E15),6) | F17: =C17-D17 | G17: =E17-C17
A18: W금융일수 표기 | B18: ROUND(W, 스위치 ②) | C18: =ROUND(C17,SW_자릿수) | D18: =ROUND(D17,SW_자릿수) | E18: =ROUND(E17,SW_자릿수)
A19: Ty수익율(%) | B19: 할인율 x 365 / 표기 W | C19: =ROUND(할인율퍼센트*연일수/C18,6) | D19: =ROUND(할인율퍼센트*연일수/D18,6) | E19: =ROUND(할인율퍼센트*연일수/E18,6) | F19: =C19-D19 | G19: =E19-C19
A20: 미회수 잔량 W | B20: Σ 구성비 x E[d²] / W | C20: =ROUND(SUMPRODUCT(Ed2범위,C12:C15)/C17,6) | D20: =ROUND(SUMPRODUCT(Ed2범위,D12:D15)/D17,6) | E20: =ROUND(SUMPRODUCT(Ed2범위,E12:E15)/E17,6)
A21: 미회수 잔량 Ty(%) | B21: 할인율 x 365 / ROUND(미회수 W) | C21: =ROUND(할인율퍼센트*연일수/ROUND(C20,SW_자릿수),6) | D21: =ROUND(할인율퍼센트*연일수/ROUND(D20,SW_자릿수),6) | E21: =ROUND(할인율퍼센트*연일수/ROUND(E20,SW_자릿수),6)
A23: 확인 | B23: 내용 | H23: 출처
A24: 설계 사실 | B24: 로스터 8곳의 금액 구성비를 금액 실측(Figma 2782:5879 · 미리 받는 돈 상세 (analysis/figma_02_가맹점화면.md §3-2))과 같게 맞췄다. 그래서 (다)와 (가)의 차가 0 이다. | H24: platform_duration.py BOOK_MIX · daily_ledger.py BOOKROWS
A25: 확인 문항 1 | B25: 엑셀의 플랫폼 비중은 시장 평균 참고값인가, 화면 계산에 쓰는 값인가. 워드는 금액으로 가중하라 하고 엑셀은 이용자 수로 가중돼 있어 둘이 다르다. | H25: 정산주기.xlsx 비중 시트 · 용어 정의.docx [1번 이미지] 4~5번 문단
A26: 확인 문항 2 | B26: 배달앱/전체 = 0.35 와 카드 65% 는 매출액 기준인가 이용자 수 기준인가. | H26: 정산주기.xlsx 비중 H5 · D4:F4
A28: 배달앱/전체 | B28: 카드 | C28: 배민 | D28: 쿠팡이츠 | E28: 요기요 | F28: W금융일수 | G28: Ty수익율(%) | H28: 기준선(0.35) 대비 | I28: 비고
A29: 0.3 | B29: =1-$A29 | C29: =$A29*INDEX(MAU배분범위,1) | D29: =$A29*INDEX(MAU배분범위,2) | E29: =$A29*INDEX(MAU배분범위,3) | F29: =ROUND(B29*INDEX(평균금융일수범위,1)+C29*INDEX(평균금융일수범위,2)+D29*INDEX(평균금융일수범위,3)+E29*INDEX(평균금융일수범위,4),6) | G29: =ROUND(할인율퍼센트*연일수/ROUND(F29,SW_자릿수),6) | H29: =TEXT(F29-$F$30,"0.0000")&"일 · "&TEXT(G29-$G$30,"0.00")&"%p"
A30: 0.35 | B30: =1-$A30 | C30: =$A30*INDEX(MAU배분범위,1) | D30: =$A30*INDEX(MAU배분범위,2) | E30: =$A30*INDEX(MAU배분범위,3) | F30: =ROUND(B30*INDEX(평균금융일수범위,1)+C30*INDEX(평균금융일수범위,2)+D30*INDEX(평균금융일수범위,3)+E30*INDEX(평균금융일수범위,4),6) | G30: =ROUND(할인율퍼센트*연일수/ROUND(F30,SW_자릿수),6) | H30: =TEXT(F30-$F$30,"0.0000")&"일 · "&TEXT(G30-$G$30,"0.00")&"%p"
A31: 0.4 | B31: =1-$A31 | C31: =$A31*INDEX(MAU배분범위,1) | D31: =$A31*INDEX(MAU배분범위,2) | E31: =$A31*INDEX(MAU배분범위,3) | F31: =ROUND(B31*INDEX(평균금융일수범위,1)+C31*INDEX(평균금융일수범위,2)+D31*INDEX(평균금융일수범위,3)+E31*INDEX(평균금융일수범위,4),6) | G31: =ROUND(할인율퍼센트*연일수/ROUND(F31,SW_자릿수),6) | H31: =TEXT(F31-$F$30,"0.0000")&"일 · "&TEXT(G31-$G$30,"0.00")&"%p"
A32: =배달앱비중 | B32: =1-$A32 | C32: =$A32*INDEX(MAU배분범위,1) | D32: =$A32*INDEX(MAU배분범위,2) | E32: =$A32*INDEX(MAU배분범위,3) | F32: =ROUND(B32*INDEX(평균금융일수범위,1)+C32*INDEX(평균금융일수범위,2)+D32*INDEX(평균금융일수범위,3)+E32*INDEX(평균금융일수범위,4),6) | G32: =ROUND(할인율퍼센트*연일수/ROUND(F32,SW_자릿수),6) | H32: =TEXT(F32-$F$30,"0.0000")&"일 · "&TEXT(G32-$G$30,"0.00")&"%p" | I32: 현재 입력 (입력 B47)
A33: =배달앱금액비중 | B33: =1-$A33 | C33: =$A33*INDEX(MAU배분범위,1) | D33: =$A33*INDEX(MAU배분범위,2) | E33: =$A33*INDEX(MAU배분범위,3) | F33: =ROUND(B33*INDEX(평균금융일수범위,1)+C33*INDEX(평균금융일수범위,2)+D33*INDEX(평균금융일수범위,3)+E33*INDEX(평균금융일수범위,4),6) | G33: =ROUND(할인율퍼센트*연일수/ROUND(F33,SW_자릿수),6) | H33: =TEXT(F33-$F$30,"0.0000")&"일 · "&TEXT(G33-$G$30,"0.00")&"%p" | I33: 금액 실측 배달앱/전체 (입력 C40)
A34: 배달 3사 내부 배분 | B34: =TEXT(INDEX(MAU배분범위,1),"0.0000")&" : "&TEXT(INDEX(MAU배분범위,2),"0.0000")&" : "&TEXT(INDEX(MAU배분범위,3),"0.0000") | H34: 정산주기.xlsx 비중 D5:F5 (MAU 비)

Sheet 화면대조
A1: 구분 | B1: 항목 | C1: 엑셀 값 | D1: 산출 경로 | E1: 화면 표시값 | F1: 차이 | G1: 판정 | H1: 출처
A2: 화면 표시값 원본 | B2: 투자실행액 | D2: ledger_facts.json exec | E2: 80000000 | H2: ledger_facts.json
A3: 화면 표시값 원본 | B3: 순현금 | D3: ledger_facts.json cash | E3: 20000000 | H3: ledger_facts.json
A4: 화면 표시값 원본 | B4: 투자자산 | D4: ledger_facts.json total | E4: 100000000 | H4: ledger_facts.json
A5: 화면 표시값 원본 | B5: 투자실행액 비중(%) | D5: exec ÷ total (roster16_model EXEC_SHARE) | E5: 80 | H5: ledger_facts.json
A6: 화면 표시값 원본 | B6: 순현금 비중(%) | D6: cash ÷ total (roster16_model CASH_SHARE) | E6: 20 | H6: ledger_facts.json
A7: 화면 표시값 원본 | B7: W금융일수 raw | D7: ledger_facts.json wRaw | E7: 3.039607 | H7: ledger_facts.json
A8: 화면 표시값 원본 | B8: W금융일수 표기 | D8: ledger_facts.json w | E8: 3.04 | H8: ledger_facts.json
A9: 화면 표시값 원본 | B9: Ty수익율(%) | D9: ledger_facts.json ty | E9: 13.21 | H9: ledger_facts.json
A10: 화면 표시값 원본 | B10: S입금부족율 raw(%) | D10: ledger_facts.json sRaw | E10: 0.074428 | H10: ledger_facts.json
A11: 화면 표시값 원본 | B11: S입금부족율 표기(%) | D11: ledger_facts.json s | E11: 0.07 | H11: ledger_facts.json
A12: 화면 표시값 원본 | B12: 할인율(%) | D12: ledger_facts.json rate | E12: 0.11 | H12: ledger_facts.json
A13: 화면 표시값 원본 | B13: 하루 평균 투자실행금 | D13: ledger_facts.json dayAvg | E13: 26113907 | H13: ledger_facts.json
... A89: 화면 표시값 원본 | B89: 한강커피 잠원점 — 비중(%) | D89: ledger_facts.json merchants[7] | E89: 5 | H89: ledger_facts.json
A90: 구분 | B90: 항목 | C90: 엑셀 값 | D90: 산출 경로 | E90: 화면 표시값 | F90: 차이 | G90: 판정 | H90: 출처
A91: 항등식 | B91: 좌변 — 투자실행액 (채권 미회수 Σ Ai) | C91: =기간집계!B38 | D91: 기간집계 B38 | E91: =가맹점!B18 | F91: =IFERROR(C91-E91,"") | G91: =IFERROR(IF(ABS(F91)<=0.5,"일치","차이"),"") | H91: 우변 — 하루 선정산액 합계 x (1-r) x W. 채권 시트의 미회수 건수는 기본 조합에서 푼 정수라 스위치 ③④를 바꾸면 좌변이 그만큼 어긋난다.
A92: 불변식 | B92: 투자실행액 | C92: =기간집계!B44 | D92: 기간집계 B44 | E92: =$E$2 | F92: =IFERROR(C92-E92,"") | G92: =IFERROR(IF(ABS(F92)<=0.5,"일치","차이"),"") | H92: 화면대조 E2
A93: 불변식 | B93: 순현금 | C93: =기간집계!B45 | D93: 기간집계 B45 | E93: =$E$3 | F93: =IFERROR(C93-E93,"") | G93: =IFERROR(IF(ABS(F93)<=0.5,"일치","차이"),"") | H93: 화면대조 E3
A94: 불변식 | B94: 투자자산 | C94: =기간집계!B46 | D94: 기간집계 B46 | E94: =$E$4 | F94: =IFERROR(C94-E94,"") | G94: =IFERROR(IF(ABS(F94)<=0.5,"일치","차이"),"") | H94: 화면대조 E4
A95: 불변식 | B95: 투자실행액 비중(%) | C95: =ROUND(기간집계!B47*100,1) | D95: 기간집계 B47 | E95: =$E$5 | F95: =IFERROR(C95-E95,"") | G95: =IFERROR(IF(ABS(F95)<=0.005,"일치","차이"),"") | H95: 화면대조 E5
A96: 불변식 | B96: 순현금 비중(%) | C96: =ROUND(기간집계!B48*100,1) | D96: 기간집계 B48 | E96: =$E$6 | F96: =IFERROR(C96-E96,"") | G96: =IFERROR(IF(ABS(F96)<=0.005,"일치","차이"),"") | H96: 화면대조 E6
A97: 불변식 | B97: W금융일수 (표기) | C97: =기간집계!B42 | D97: 기간집계 B42 | E97: =$E$8 | F97: =IFERROR(C97-E97,"") | G97: =IFERROR(IF(ABS(F97)<=0.0005,"일치","차이"),"") | H97: 화면대조 E8
A98: 불변식 | B98: W금융일수 (raw · 소수 6자리) | C98: =ROUND(기간집계!B41,6) | D98: 기간집계 B41 | E98: =$E$7 | F98: =IFERROR(C98-E98,"") | G98: =IFERROR(IF(ABS(F98)<=5e-07,"일치","차이"),"") | H98: 화면대조 E7
A99: 불변식 | B99: Ty수익율(%) | C99: =기간집계!B43 | D99: 기간집계 B43 | E99: =$E$9 | F99: =IFERROR(C99-E99,"") | G99: =IFERROR(IF(ABS(F99)<=0.005,"일치","차이"),"") | H99: 화면대조 E9
A100: 불변식 | B100: 로스터 건수 | C100: =가맹점!B19 | D100: 가맹점 B19 | E100: =$E$19 | F100: =IFERROR(C100-E100,"") | G100: =IFERROR(IF(ABS(F100)<=0.5,"일치","차이"),"") | H100: 화면대조 E19
A101: 불변식 | B101: 서명 대기 건수 | C101: =COUNTIF(계약상태범위,"서명 대기") | D101: 입력 J열 | E101: =$E$20 | F101: =IFERROR(C101-E101,"") | G101: =IFERROR(IF(ABS(F101)<=0.5,"일치","차이"),"") | H101: 화면대조 E20
A102: 불변식 | B102: 비중 합(%) | C102: =SUM(가맹점!AC2:AC9) | D102: 가맹점 AC열 (최대잉여법) | E102: 100 | F102: =IFERROR(C102-E102,"") | G102: =IFERROR(IF(ABS(F102)<=0.005,"일치","차이"),"") | H102: 비중 합 100.0 불변
A103: 불변식 | B103: 채권 Di 최소 | C103: =MIN(채권!$H$2:$H$1281) | D103: 채권 H열 | E103: =$E$17 | F103: =IFERROR(C103-E103,"") | G103: =IFERROR(IF(ABS(F103)<=0.5,"일치","차이"),"") | H103: 화면대조 E17
A104: 불변식 | B104: 채권 Di 최대 | C104: =MAX(채권!$H$2:$H$1281) | D104: 채권 H열 | E104: =$E$18 | F104: =IFERROR(C104-E104,"") | G104: =IFERROR(IF(ABS(F104)<=0.5,"일치","차이"),"") | H104: 화면대조 E18
A105: 불변식 | B105: 플랫폼 구성비 합 | C105: =SUM(구성비범위) | D105: 입력 C28:C31 | E105: 1 | F105: =IFERROR(C105-E105,"") | G105: =IFERROR(IF(ABS(F105)<=1e-07,"일치","차이"),"") | H105: 합 1 (구성상)
A106: 교차 | B106: 미회수 잔량 W — 채권 vs 도수표 | C106: =기간집계!B40 | D106: 기간집계 B40 | E106: =플랫폼!B21 | F106: =IFERROR(C106-E106,"") | G106: =IFERROR(IF(ABS(F106)<=0.0005,"일치","차이"),"") | H106: 플랫폼 B21 = 가중 E[d²] / W
A107: 교차 | B107: 미회수 잔량 Ty(%) | C107: =기간집계!B56 | D107: 기간집계 B56 | E107: ='가중치 대조'!C21 | F107: =IFERROR(C107-E107,"") | G107: =IFERROR(IF(ABS(F107)<=0.02,"일치","차이"),"") | H107: 가중치 대조 C21
A108: 교차 | B108: W금융일수 — 구성비 x 평균 금융일수 | C108: =플랫폼!B17 | D108: 플랫폼 B17 | E108: =$E$7 | F108: =IFERROR(C108-E108,"") | G108: =IFERROR(IF(ABS(F108)<=5e-07,"일치","차이"),"") | H108: 화면대조 E7
A109: 교차 | B109: 로스터 금액가중 구성비 — 카드 | C109: =가맹점!B28 | D109: 가맹점 B28 | E109: =INDEX(구성비범위,1) | F109: =IFERROR(C109-E109,"") | G109: =IFERROR(IF(ABS(F109)<=1e-07,"일치","차이"),"") | H109: 입력 C28
A110: 불변식 | B110: S입금부족율(%) | C110: =ROUND(기간집계!B51,2) | D110: 기간집계 B51 | E110: =$E$11 | F110: =IFERROR(C110-E110,"") | G110: =IFERROR(IF(ABS(F110)<=0.005,"일치","차이"),"") | H110: 화면대조 E11
A111: 불변식 | B111: 투자실행액 = 입력 목표 | C111: =기간집계!B44 | D111: 기간집계 B44 | E111: =투자실행액목표 | F111: =IFERROR(C111-E111,"") | G111: =IFERROR(IF(ABS(F111)<=0.5,"일치","차이"),"") | H111: 입력 C7 = C5 - C8
A112: 불변식 | B112: 투자자산 = 총 투자자산 | C112: =기간집계!B46 | D112: 기간집계 B46 | E112: =총투자자산 | F112: =IFERROR(C112-E112,"") | G112: =IFERROR(IF(ABS(F112)<=0.5,"일치","차이"),"") | H112: 입력 C5
A113: 가맹점 | B113: 김성호떡볶이 본점 — W 표기 | C113: =가맹점!T2 | D113: 가맹점 T2 | E113: =$E$43 | F113: =IFERROR(C113-E113,"") | G113: =IFERROR(IF(ABS(F113)<=0.0005,"일치","차이"),"") | H113: 화면대조 E43
A114: 가맹점 | B114: 초록치킨 서초점 — W 표기 | C114: =가맹점!T3 | D114: 가맹점 T3 | E114: =$E$49 | F114: =IFERROR(C114-E114,"") | G114: =IFERROR(IF(ABS(F114)<=0.0005,"일치","차이"),"") | H114: 화면대조 E49
A115: 가맹점 | B115: 김밥나라 — W 표기 | C115: =가맹점!T4 | D115: 가맹점 T4 | E115: =$E$55 | F115: =IFERROR(C115-E115,"") | G115: =IFERROR(IF(ABS(F115)<=0.0005,"일치","차이"),"") | H115: 화면대조 E55
...

Sheet 산식
A1: 출처 절 | B1: 대표 정의서 원문 | C1: 이 통합문서의 셀
A2: [1번 이미지] | B2: 투자 실행액: ‘유동화투자자와 정산금채권 재양도 합의서 체결한 가맹점들의 순지급액들 중 회수되지 않은 순지급액 합계’ x (1- 유동화투자자의 할인율) | C2: 기간집계 B44 · 화면대조 2행
A3: [1번 이미지] | B3: 유동화투자자의 할인율 = 0.11% 예정 | C3: 입력 C2 · C3
A4: [1번 이미지] | B4: 순현금: 조회시점 현재의 ‘유동화투자자에게 할당된 쿠콘제공 가상계좌’의 현금잔액 | C4: 입력 C8 · 기간집계 B45
A5: [1번 이미지] | B5: w금융일수 = Σ Ai x Di / Σ Ai | C5: 기간집계 B34 · 가중치 대조 C17 — 가중치는 금액(Ai)
A6: [1번 이미지] | B6: Ai = ID가 i인 대상정산금채권의 순지급액 x (1- 유동화투자자의 할인율) | C6: 채권 J열 — w금융일수의 가중치
A7: [1번 이미지] | B7: Di = ID가 i인 다상정산금채권의 금융일수 | C7: 채권 H열
A8: [1번 이미지] | B8: 대상정산금채권: 가맹점ID가 ‘유동화투자자와 정산금채권 재양도 합의서 체결한 가맹점’의 ID이면서, 선정산일자가 상기 합의서상의 효력기간에 해당하는 정산금채권 | C8: 채권 시트 전 행 (선정산일 축 40일)
A9: [1번 이미지] | B9: 각 정산금채권의 ID = 가맹점ID & 플랫폼ID & 매출일자(YYYYMMDD) | C9: 채권 D·E·F열
A10: [1번 이미지] | B10: 플랫폼ID: 각 카드사, 각 배달플랫폼에 페이허그가 할당한 ID | C10: 입력 A28:A31
A11: [1번 이미지] | B11: 금융일수 = 선정산일로부터 정산예정일까지의 한편넣기 일수 (예, 선정산일 =260827, 정산예정일 = 260808 이면 금융일수 = 1) | C11: 채권 H열 (정산주기.xlsx N6:Q370 실측)
A12: [1번 이미지] | B12: S입금부족율 = Σ SLi / Σ SAi | C12: 기간집계 B51
... A46: [2번 이미지] | B46: 투자실행금액 대비 ty수익율 (이미지의 ⑥) = (이미지의 ④ / 이미지의 ③) x 365 / 이미지의 ⑤ | C46: 기간집계 B18 = (B13 / 입력 C18) x 365 / B17 — ③ 지시 대상 미확정이라 입력 C18 가 비어 있고 그동안 「미확정」. 대표 주석 「계산식 다시 확인해볼것」
